Workbook

Sheet 基础数据
A1: 日期
A2: 45836 | J2: 二车间
B3: 甲班 | E3: 其他 | J3: A班 | M3: 其他
B4: 铅（%） | C4: 锌（%） | D4: 银（g/T） | J4: 铅（%） | K4: 锌（%） | L4: 银（g/T） | O4: 铅 | P4: ='2车间表1'!L14 -> 0
A5: 原矿 | E5: 运转时间 | I5: 原矿 | M5: 运转时间
A6: 混精 | E6: 处理量 | I6: 混精 | M6: 处理量 | O6: 银 | P6: ='2车间表1'!M14 -> 0.00
A7: 混尾 | E7: 主细 | I7: 混尾 | M7: 主细
A8: 再选精矿 | E8: 再细 | I8: 再选精矿 | M8: 再细
A9: 再选尾矿 | E9: 水分 | F9: 3 | I9: 再选尾矿 | M9: 水分
A10: 过铅 | E10: 处理量/h | F10: =F6/F5 -> #DIV/0! | I10: 过铅 | M10: 处理量/h | N10: =N6/N5 -> #DIV/0!
A11: 铅精 | I11: 铅精 | R11: 原矿品位Pb+Zn
A12: 锌精 | I12: 锌精 | R12: ='班组统计台账（3%）日累'!E8+'班组统计台账（3%）日累'!F8 -> 3.91
A13: 尾矿 | I13: 尾矿
R14: 回收率
B15: 乙班 | E15: 其他 | J15: B班 | M15: 其他
B16: 铅（%） | C16: 锌（%） | D16: 银（g/T） | J16: 铅（%） | K16: 锌（%） | L16: 银（g/T） | O16: 铅 | P16: ='2车间表1'!L15 -> 0 | R16: ='班组统计台账（3%）日累'!AH8 -> 97.34854
A17: 原矿 | B17: 3.75 | D17: 161 | E17: 运转时间 | F17: 8 | I17: 原矿 | M17: 运转时间 | R17: ='班组统计台账（3%）日累'!AJ8 -> 99.810274
A18: 混精 | E18: 处理量 | F18: 128 | I18: 混精 | M18: 处理量 | O18: 银 | P18: ='2车间表1'!M15 -> 0.00
A19: 混尾 | E19: 主细 | I19: 混尾 | M19: 主细
A20: 再选精矿 | E20: 再细 | I20: 再选精矿 | M20: 再细
A21: 再选尾矿 | E21: 水分 | F21: 3 | I21: 再选尾矿 | M21: 水分 | R21: ='班组统计台账（3%）日累'!AB8 -> 0.1100507
A22: 过铅 | E22: 处理量/h | F22: =F18/F17 -> 16 | I22: 过铅 | M22: 处理量/h | N22: =N18/N17 -> #DIV/0! | R22: ='班组统计台账（3%）日累'!AD8 -> 0.39373621
A23: 铅精 | B23: 65.27 | D23: 3352 | I23: 铅精
A24: 锌精 | I24: 锌精
A25: 尾矿 | B25: 0.13 | D25: 8 | I25: 尾矿
B27: 丙班 | E27: 其他 | J27: C班 | M27: 其他
B28: 铅（%） | C28: 锌（%） | D28: 银（g/T） | G28: 铅 | H28: ='1车间表1'!L16 -> 97.922147 | J28: 铅（%） | K28: 锌（%） | L28: 银（g/T） | O28: 铅 | P28: ='2车间表1'!L16 -> 0
A29: 原矿 | B29: 4.07 | D29: 230 | E29: 运转时间 | F29: 8 | I29: 原矿 | M29: 运转时间
A30: 混精 | E30: 处理量 | F30: 128 | G30: 银 | H30: ='1车间表1'!M16 -> 88.686423 | I30: 混精 | M30: 处理量 | O30: 银 | P30: ='2车间表1'!M16 -> 0.00
A31: 混尾 | E31: 主细 | I31: 混尾 | M31: 主细
A32: 再选精矿 | E32: 再细 | I32: 再选精矿 | M32: 再细
A33: 再选尾矿 | E33: 水分 | F33: 3 | I33: 再选尾矿 | M33: 水分
A34: 过铅 | E34: 处理量/h | F34: =F30/F29 -> 16 | I34: 过铅 | M34: 处理量/h | N34: =N30/N29 -> #DIV/0! | P34: 2871
A35: 铅精 | B35: 66.04 | D35: 3380 | I35: 铅精 | P35: =P34-D35 -> -509
A36: 锌精 | I36: 锌精
A37: 尾矿 | B37: 0.09 | D37: 4 | I37: 尾矿
B56: 甲 | C56: 乙 | D56: 丙 | E56: A | F56: B | G56: C
B57: ='1车间表1'!H7 -> 0 | C57: ='1车间表1'!H8 -> 124.16 | D57: ='1车间表1'!H9 -> 124.16 | E57: ='2车间表1'!H7 -> 0 | F57: ='2车间表1'!H8 -> 0 | G57: ='2车间表1'!H9 -> 0
B58: =#REF! -> #REF! | C58: =#REF! -> #REF! | D58: =#REF! -> #REF! | E58: =#REF! -> #REF! | F58: =#REF! -> #REF! | G58: =#REF! -> #REF!
B59: =#REF! -> #REF! | C59: =#REF! -> #REF! | D59: =#REF! -> #REF! | E59: =#REF! -> #REF! | F59: =#REF! -> #REF! | G59: =#REF! -> #REF!
...

Sheet 1车间表1
B2: 选矿厂生产日报表（金属平衡表）
M4: =基础数据!A2 -> 45836
B5: 种类 | C5: 班别 | D5: 细度％ | E5: 磨矿时间（h） | F5: 处 理 量 | L5: 金 属 量
F6: 湿量（T） | G6: 水份（%） | H6: 干量（T） | I6: 铅（%） | J6: 锌（%） | K6: 银（g/t） | L6: 铜（T） | M6: 铅（T） | N6: 锌（T） | O6: 银（Kg）
B7: 原矿 | C7: 甲 | D7: =基础数据!F7 -> 0 | E7: =基础数据!F5 -> 0 | F7: =基础数据!F6 -> 0 | G7: =基础数据!F9 -> 3 | H7: =F7*(1-G7%) -> 0 | I7: =基础数据!B5 -> 0 | K7: =基础数据!D5 -> 0 | M7: =H7*I7/100 -> 0 | O7: =H7*K7/1000 -> 0
C8: 乙 | D8: =基础数据!F19 -> 0 | E8: =基础数据!F17 -> 8 | F8: =基础数据!F18 -> 128 | G8: =基础数据!F21 -> 3 | H8: =F8*(1-G8%) -> 124.16 | I8: =基础数据!B17 -> 3.75 | K8: =基础数据!D17 -> 161 | M8: =H8*I8/100 -> 4.656 | O8: =H8*K8/1000 -> 19.98976
C9: 丙 | D9: =基础数据!F31 -> 0 | E9: =基础数据!F29 -> 8 | F9: =基础数据!F30 -> 128 | G9: =基础数据!F33 -> 3 | H9: =F9*(1-G9%) -> 124.16 | I9: =基础数据!B29 -> 4.07 | K9: =基础数据!D29 -> 230 | M9: =H9*I9/100 -> 5.053312 | O9: =H9*K9/1000 -> 28.5568
C10: 日累 | D10: =IF(ISERROR((D7*H7+D8*H8+D9*H9)/(H7+H8+H9)),"0.00",(D7*H7+D8*H8+D9*H9)/(H7+H8+H9)) -> 0 | E10: =E7+E8+E9 -> 16 | F10: =F7+F8+F9 -> 256 | G10: =IF(ISERROR((F10-H10)/F10*100),"0.00",(F10-H10)/F10*100) -> 3 | H10: =H7+H8+H9 -> 248.32 | I10: =IF(ISERROR(M10/H10*100),"0.00",M10/H10*100) -> 3.91 | K10: =IF(ISERROR(O10/H10*1000),"0",O10/H10*1000) -> 195.5 | M10: =M7+M8+M9 -> 9.709312 | O10: =O7+O8+O9 -> 48.54656 | S10: =((I7-F24)/(F14-F24))*F14/I7*100 -> #DIV/0!
C11: 月累 | D11: =IF(ISERROR((D35*H35+H10*D10)/H11),"0.00",(D35*H35+H10*D10)/H11) -> 0 | E11: =E10+E35 -> 16 | F11: =F10+F35 -> 256 | G11: =IF(ISERROR((F11-H11)/F11*100),"0.00",(F11-H11)/F11*100) -> 3 | H11: =H10+H35 -> 248.32 | I11: =IF(ISERROR(M11/H11*100),"0.00",M11/H11*100) -> 3.91 | K11: =IF(ISERROR(O11/H11*1000),"0",O11/H11*1000) -> 195.5 | M11: =M10+M35 -> 9.709312 | O11: =O10+O35 -> 48.54656
B12: 种类 | C12: 班别 | D12: 干量（T） | E12: 分 布 率 | I12: 金 属 量 | L12: 回收率（%） | N12: 产率（%） | O12: 富集比
E13: 铜（%） | F13: 铅（%） | G13: 锌（%） | H13: 银（g/t） | I13: 铅（T） | J13: 锌（T） | K13: 银（Kg） | L13: 铜铅锌 | M13: 银
B14: 铅精矿 | C14: 甲 | D14: =N14*H7/100 -> 0 | F14: =基础数据!B11 -> 0 | G14: =基础数据!C11 -> 0 | H14: =基础数据!D11 -> 0 | I14: =D14*F14/100 -> 0 | J14: =D14*G14/100 -> 0 | K14: =D14*H14/1000 -> 0 | L14: =O14*N14 -> 0 | M14: =IF(ISERROR(H14/K7*N14),"0.00",H14/K7*N14) -> 0.00 | N14: =IF(ISERROR(S14/T14),"0.00",S14/T14) -> 0.00 | O14: =IF(ISERROR(F14/I7),"0.00",F14/I7) -> 0.00 | S14: =(I7-F24)*100 -> 0 | T14: =F14-F24 -> 0
C15: 乙 | D15: =N15*H8/100 -> 6.8998956 | F15: =基础数据!B23 -> 65.27 | G15: =基础数据!C23 -> 0 | H15: =基础数据!D23 -> 3352 | I15: =D15*F15/100 -> 4.5035619 | J15: =D15*G15/100 -> 0 | K15: =D15*H15/1000 -> 23.12845 | L15: =O15*N15 -> 96.725985 | M15: =IF(ISERROR(H15/K8*N15),"0.00",H15/K8*N15) -> 115.70149 | N15: =IF(ISERROR(S15/T15),"0.00",S15/T15) -> 5.5572613 | O15: =IF(ISERROR(F15/I8),"0.00",F15/I8) -> 17.405333 | S15: =(I8-F25)*100 -> 362 | T15: =F15-F25 -> 65.14
C16: 丙 | D16: =N16*H9/100 -> 7.4929007 | F16: =基础数据!B35 -> 66.04 | G16: =基础数据!C35 -> 0 | H16: =基础数据!D35 -> 3380 | I16: =D16*F16/100 -> 4.9483116 | J16: =D16*G16/100 -> 0 | K16: =D16*H16/1000 -> 25.326004 | L16: =O16*N16 -> 97.922147 | M16: =IF(ISERROR(H16/K9*N16),"0.00",H16/K9*N16) -> 88.686423 | N16: =IF(ISERROR(S16/T16),"0.00",S16/T16) -> 6.0348749 | O16: =IF(ISERROR(F16/I9),"0.00",F16/I9) -> 16.226044 | S16: =(I9-F26)*100 -> 398 | T16: =F16-F26 -> 65.95
C17: 日累 | D17: =D14+D15+D16 -> 14.392796 | F17: =IF(ISERROR(I17/D17*100),"0.00",I17/D17*100) -> 65.670863 | G17: =IF(ISERROR(J17/D17*100),"0.00",J17/D17*100) -> 0 | H17: =IF(ISERROR(K17/D17*1000),"0",K17/D17*1000) -> 3366.5768 | I17: =I14+I15+I16 -> 9.4518735 | J17: =J14+J15+J16 -> 0 | K17: =K14+K15+K16 -> 48.454454 | L17: =IF(ISERROR(I17/M10*100),"0.00",I17/M10*100) -> 97.34854 | M17: =IF(ISERROR(K17/O10*100),"0.00",K17/O10*100) -> 99.810274 | N17: =IF(ISERROR(L17/O17),"0.00",L17/O17) -> 5.7960681 | O17: =IF(ISERROR(F17/I10),"0.00",F17/I10) -> 16.795617
C18: 月累 | D18: =D17+D36 -> 14.392796 | F18: =IF(ISERROR(I18/D18*100),"0.00",I18/D18*100) -> 65.670863 | G18: =IF(ISERROR(J18/D18*100),"0.00",J18/D18*100) -> 0 | H18: =IF(ISERROR(K18/D18*1000),"0",K18/D18*1000) -> 3366.5768 | I18: =I17+I36 -> 9.4518735 | J18: =J17+J36 -> 0 | K18: =K17+K36 -> 48.454454 | L18: =IF(ISERROR(I18/M11*100),"0.00",I18/M11*100) -> 97.34854 | M18: =IF(ISERROR(K18/O11*100),"0.00",K18/O11*100) -> 99.810274 | N18: =IF(ISERROR(L18/O18),"0.00",L18/O18) -> 5.7960681 | O18: =IF(ISERROR(F18/I11),"0.00",F18/I11) -> 16.795617
B19: 锌精矿 | C19: 甲
C20: 乙
C21: 丙
C22: 日累
C23: 月累
B24: 尾矿 | C24: 甲 | D24: =H7-D14-D19 -> 0 | F24: =基础数据!B13 -> 0 | H24: =基础数据!D13 -> 0 | I24: =M7-I14-I19 -> 0 | J24: =N7-J14-J19 -> 0 | K24: =O7-K14-K19 -> 0
C25: 乙 | D25: =H8-D15-D20 -> 117.2601 | F25: =基础数据!B25 -> 0.13 | H25: =基础数据!D25 -> 8 | I25: =M8-I15-I20 -> 0.15243814 | J25: =N8-J15-J20 -> 0 | K25: =O8-K15-K20 -> -3.1386901
C26: 丙 | D26: =H9-D16-D21 -> 116.6671 | F26: =基础数据!B37 -> 0.09 | H26: =基础数据!D37 -> 4 | I26: =M9-I16-I21 -> 0.10500039 | J26: =N9-J16-J21 -> 0 | K26: =O9-K16-K21 -> 3.2307957
C27: 日累 | D27: =D24+D25+D26 -> 233.9272 | F27: =IF(ISERROR(I27/D27*100),"0.00",I27/D27*100) -> 0.1100507 | H27: =IF(ISERROR(K27/D27*1000),"0",K27/D27*1000) -> 0.39373621 | I27: =I24+I25+I26 -> 0.25743853 | J27: =J24+J25+J26 -> 0 | K27: =K24+K25+K26 -> 0.092105611
C28: 月累 | D28: =D27+D38 -> 233.9272 | F28: =IF(ISERROR(I28/D28*100),"0.00",I28/D28*100) -> 0.1100507 | H28: =IF(ISERROR(K28/D28*1000),"0",K28/D28*1000) -> 0.39373621 | I28: =I27+I38 -> 0.25743853 | J28: =J27+J38 -> 0 | K28: =K27+K38 -> 0.092105611
D29: 质检负责人： | K29: 制表人：
C34: 昨日月累：
B35: 原矿月累
B36: 铅精月累
B37: 锌精月累
B38: 尾矿月累
C44: 今日月累：
B45: 原矿月累 | D45: =D11 -> 0 | E45: =E11 -> 16 | F45: =F11 -> 256 | H45: =H11 -> 248.32 | L45: =L11 -> 0 | M45: =M11 -> 9.709312 | N45: =N11 -> 0 | O45: =O11 -> 48.54656
B46: 铅精月累 | D46: =D18 -> 14.392796 | I46: =I18 -> 9.4518735 | J46: =J18 -> 0 | K46: =K18 -> 48.454454
B47: 锌精月累 | D47: =D23 -> 0 | I47: =I23 -> 0 | J47: =J23 -> 0 | K47: =K23 -> 0
B48: 尾矿月累 | D48: =D28 -> 233.9272 | I48: =I28 -> 0.25743853 | J48: =J28 -> 0 | K48: =K28 -> 0.092105611

Sheet 1车间表2
B2: 选矿厂生产月累统计表 | O2: =(J13+K17)/(J7+K7)*100 -> #DIV/0!
O3: =(J14+K18)/(J8+K8)*100 -> 96.725985
J4: =基础数据!A2 -> 45836 | O4: =(J15+K19)/(J9+K9)*100 -> 97.922147
B5: 种类 | C5: 班别 | D5: 细度％ | E5: 磨矿时间（h） | F5: 干量（T） | G5: 品 位 | J5: 金 属 量 | O5: =(J16+K20)/(J10+K10)*100 -> 97.34854
G6: 铅（%） | H6: 锌（%） | I6: 银（g/t） | J6: 铅（T） | K6: 锌（T） | L6: 银（Kg）
B7: 原矿 | C7: 甲月累 | D7: =IF(ISERROR((D32*F32+'1车间表1'!D7*'1车间表1'!H7)/'1车间表2'!F7),"0.00",(D32*F32+'1车间表1'!D7*'1车间表1'!H7)/'1车间表2'!F7) -> 0.00 | E7: =E32+'1车间表1'!E7 -> 0 | F7: =F32+'1车间表1'!H7 -> 0 | G7: =IF(ISERROR(J7/F7*100),"0.00",J7/F7*100) -> 0.00 | I7: =IF(ISERROR(L7/F7*1000),"0",L7/F7*1000) -> 0 | J7: =J32+'1车间表1'!M7 -> 0 | L7: =L32+'1车间表1'!O7 -> 0 | N7: =D7 -> 0.00 | O7: =F7/E7 -> #DIV/0! | P7: =#REF! -> #REF! | Q7: =G7 -> 0.00 | R7: =H7 -> 0 | S7: =I7 -> 0 | T7: =#REF! -> #REF! | U7: =#REF! -> #REF! | V7: =#REF! -> #REF! | W7: =#REF! -> #REF! | X7: =#REF! -> #REF! | Y7: =G13 -> 0.00 | Z7: =H13 -> 0 | AA7: =I13 -> 0 | AB7: =#REF! -> #REF! | AC7: =G17 -> 0 | AD7: =H17 -> 0 | AE7: =I17 -> 0 | AF7: =#REF! -> #REF! | AG7: =G21 -> 0.00 | AH7: =H21 -> 0 | AI7: =I21 -> 0 | AJ7: =#REF! -> #REF! | AK7: =D13 -> 0.00 | AL7: =D17 -> 0 | AM7: =E21 -> 0
C8: 乙月累 | D8: =IF(ISERROR((D33*F33+'1车间表1'!D8*'1车间表1'!H8)/'1车间表2'!F8),"0.00",(D33*F33+'1车间表1'!D8*'1车间表1'!H8)/'1车间表2'!F8) -> 0 | E8: =E33+'1车间表1'!E8 -> 8 | F8: =F33+'1车间表1'!H8 -> 124.16 | G8: =IF(ISERROR(J8/F8*100),"0.00",J8/F8*100) -> 3.75 | I8: =IF(ISERROR(L8/F8*1000),"0",L8/F8*1000) -> 161 | J8: =J33+'1车间表1'!M8 -> 4.656 | L8: =L33+'1车间表1'!O8 -> 19.98976 | N8: =D8 -> 0 | O8: =F8/E8 -> 15.52 | P8: =#REF! -> #REF! | Q8: =G8 -> 3.75 | R8: =H8 -> 0 | S8: =I8 -> 161 | T8: =#REF! -> #REF! | U8: =#REF! -> #REF! | V8: =#REF! -> #REF! | W8: =#REF! -> #REF! | X8: =#REF! -> #REF! | Y8: =G14 -> 65.27 | Z8: =H14 -> 0 | AA8: =I14 -> 3352 | AB8: =#REF! -> #REF! | AC8: =G18 -> 0 | AD8: =H18 -> 0 | AE8: =I18 -> 0 | AF8: =#REF! -> #REF! | AG8: =G22 -> 0.13 | AH8: =H22 -> 0 | AI8: =I22 -> -26.766905 | AJ8: =#REF! -> #REF! | AK8: =D14 -> 96.725985 | AL8: =D18 -> 0 | AM8: =E22 -> 0
C9: 丙月累 | D9: =IF(ISERROR((D34*F34+'1车间表1'!D9*'1车间表1'!H9)/'1车间表2'!F9),"0.00",(D34*F34+'1车间表1'!D9*'1车间表1'!H9)/'1车间表2'!F9) -> 0 | E9: =E34+'1车间表1'!E9 -> 8 | F9: =F34+'1车间表1'!H9 -> 124.16 | G9: =IF(ISERROR(J9/F9*100),"0.00",J9/F9*100) -> 4.07 | I9: =IF(ISERROR(L9/F9*1000),"0",L9/F9*1000) -> 230 | J9: =J34+'1车间表1'!M9 -> 5.053312 | L9: =L34+'1车间表1'!O9 -> 28.5568 | N9: =D9 -> 0 | O9: =F9/E9 -> 15.52 | P9: =#REF! -> #REF! | Q9: =G9 -> 4.07 | R9: =H9 -> 0 | S9: =I9 -> 230 | T9: =#REF! -> #REF! | U9: =#REF! -> #REF! | V9: =#REF! -> #REF! | W9: =#REF! -> #REF! | X9: =#REF! -> #REF! | Y9: =G15 -> 66.04 | Z9: =H15 -> 0 | AA9: =I15 -> 3380 | AB9: =#REF! -> #REF! | AC9: =G19 -> 0 | AD9: =H19 -> 0 | AE9: =I19 -> 0 | AF9: =#REF! -> #REF! | AG9: =G23 -> 0.09 | AH9: =H23 -> 0 | AI9: =I23 -> 27.692432 | AJ9: =#REF! -> #REF! | AK9: =D15 -> 97.922147 | AL9: =D19 -> 0 | AM9: =E23 -> 0
C10: 月累 | D10: =IF(ISERROR((D7*F7+D8*F8+D9*F9)/F10),"0.00",(D7*F7+D8*F8+D9*F9)/F10) -> 0 | E10: =E7+E8+E9 -> 16 | F10: =F7+F8+F9 -> 248.32 | G10: =IF(ISERROR(J10/F10*100),"0.00",J10/F10*100) -> 3.91 | I10: =IF(ISERROR(L10/F10*1000),"0",L10/F10*1000) -> 195.5 | J10: =J7+J8+J9 -> 9.709312 | L10: =L7+L8+L9 -> 48.54656 | N10: =D10 -> 0 | O10: =F10/E10 -> 15.52 | P10: =#REF! -> #REF! | Q10: =G10 -> 3.91 | R10: =H10 -> 0 | S10: =I10 -> 195.5 | T10: =#REF! -> #REF! | U10: =#REF! -> #REF! | V10: =#REF! -> #REF! | W10: =#REF! -> #REF! | X10: =#REF! -> #REF! | Y10: =G16 -> 65.670863 | Z10: =H16 -> 0 | AA10: =I16 -> 3366.5768 | AB10: =#REF! -> #REF! | AC10: =G20 -> 0 | AD10: =H20 -> 0 | AE10: =I20 -> 0 | AF10: =#REF! -> #REF! | AG10: =G24 -> 0.1100507 | AH10: =H24 -> 0 | AI10: =I24 -> 0.39373621 | AJ10: =#REF! -> #REF! | AK10: =D16 -> 97.34854 | AL10: =D20 -> 0 | AM10: =E24 -> 0
B11: 种类 | C11: 班别 | D11: 回收率（%） | F11: 干量（T） | G11: 分 布 率 | J11: 金 属 量
D12: 铜铅锌 | E12: 银 | G12: 铅（%） | H12: 锌（%） | I12: 银（g/t） | J12: 铅（T） | K12: 锌（T） | L12: 银（Kg）
B13: 铅精 | C13: 甲月累 | D13: =IF(ISERROR(J13/J7*100),"0.00",J13/J7*100) -> 0.00 | E13: =IF(ISERROR(L13/L7*100),"0.00",L13/L7*100) -> 0.00 | F13: =F35+'1车间表1'!D14 -> 0 | G13: =IF(ISERROR(J13/F13*100),"0.00",J13/F13*100) -> 0.00 | I13: =IF(ISERROR(L13/F13*1000),"0",L13/F13*1000) -> 0 | J13: =J35+'1车间表1'!I14 -> 0 | L13: =L35+'1车间表1'!K14 -> 0 | N13: =#REF!/#REF!*100 -> #REF! | O13: =J13/J7*100 -> #DIV/0! | P13: =K13/K7*100 -> #DIV/0! | Q13: =L13/L7*100 -> #DIV/0! | S13: =P13 -> #DIV/0! | T13: =P17 -> #DIV/0! | U13: =#REF! -> #REF! | V13: =P21 -> #DIV/0! | W13: =S13+T13+U13+V13 -> #DIV/0!
C14: 乙月累 | D14: =IF(ISERROR(J14/J8*100),"0.00",J14/J8*100) -> 96.725985 | E14: =IF(ISERROR(L14/L8*100),"0.00",L14/L8*100) -> 115.70149 | F14: =F36+'1车间表1'!D15 -> 6.8998956 | G14: =IF(ISERROR(J14/F14*100),"0.00",J14/F14*100) -> 65.27 | I14: =IF(ISERROR(L14/F14*1000),"0",L14/F14*1000) -> 3352 | J14: =J36+'1车间表1'!I15 -> 4.5035619 | L14: =L36+'1车间表1'!K15 -> 23.12845 | N14: =#REF!/#REF!*100 -> #REF! | O14: =J14/J8*100 -> 96.725985 | P14: =K14/K8*100 -> #DIV/0! | Q14: =L14/L8*100 -> 115.70149 | S14: =P14 -> #DIV/0! | T14: =P18 -> #DIV/0! | U14: =#REF! -> #REF! | V14: =P22 -> #DIV/0! | W14: =S14+T14+U14+V14 -> #DIV/0!
C15: 丙月累 | D15: =IF(ISERROR(J15/J9*100),"0.00",J15/J9*100) -> 97.922147 | E15: =IF(ISERROR(L15/L9*100),"0.00",L15/L9*100) -> 88.686423 | F15: =F37+'1车间表1'!D16 -> 7.4929007 | G15: =IF(ISERROR(J15/F15*100),"0.00",J15/F15*100) -> 66.04 | I15: =IF(ISERROR(L15/F15*1000),"0",L15/F15*1000) -> 3380 | J15: =J37+'1车间表1'!I16 -> 4.9483116 | L15: =L37+'1车间表1'!K16 -> 25.326004 | N15: =#REF!/#REF!*100 -> #REF! | O15: =J15/J9*100 -> 97.922147 | P15: =K15/K9*100 -> #DIV/0! | Q15: =L15/L9*100 -> 88.686423 | S15: =P15 -> #DIV/0! | T15: =P19 -> #DIV/0! | U15: =#REF! -> #REF! | V15: =P23 -> #DIV/0! | W15: =S15+T15+U15+V15 -> #DIV/0!
C16: 月累 | D16: =IF(ISERROR(J16/J10*100),"0.00",J16/J10*100) -> 97.34854 | E16: =IF(ISERROR(L16/L10*100),"0.00",L16/L10*100) -> 99.810274 | F16: =F13+F14+F15 -> 14.392796 | G16: =IF(ISERROR(J16/F16*100),"0.00",J16/F16*100) -> 65.670863 | I16: =IF(ISERROR(L16/F16*1000),"0",L16/F16*1000) -> 3366.5768 | J16: =J13+J14+J15 -> 9.4518735 | L16: =L13+L14+L15 -> 48.454454 | N16: =#REF!/#REF!*100 -> #REF! | O16: =J16/J10*100 -> 97.34854 | P16: =K16/K10*100 -> #DIV/0! | Q16: =L16/L10*100 -> 99.810274 | S16: =P16 -> #DIV/0! | T16: =P20 -> #DIV/0! | U16: =#REF! -> #REF! | V16: =P24 -> #DIV/0! | W16: =S16+T16+U16+V16 -> #DIV/0!
B17: 锌精 | C17: 甲月累 | N17: =#REF!/#REF!*100 -> #REF! | O17: =J17/J7*100 -> #DIV/0! | P17: =K17/K7*100 -> #DIV/0! | Q17: =L17/L7*100 -> #DIV/0! | S17: =N13 -> #REF! | T17: =N17 -> #REF! | U17: =#REF! -> #REF! | V17: =N21 -> #REF! | W17: =S17+T17+U17+V17 -> #REF!
C18: 乙月累 | N18: =#REF!/#REF!*100 -> #REF! | O18: =J18/J8*100 -> 0 | P18: =K18/K8*100 -> #DIV/0! | Q18: =L18/L8*100 -> 0 | S18: =N14 -> #REF! | T18: =N18 -> #REF! | U18: =#REF! -> #REF! | V18: =N22 -> #REF! | W18: =S18+T18+U18+V18 -> #REF!
C19: 丙月累 | N19: =#REF!/#REF!*100 -> #REF! | O19: =J19/J9*100 -> 0 | P19: =K19/K9*100 -> #DIV/0! | Q19: =L19/L9*100 -> 0 | S19: =N15 -> #REF! | T19: =N19 -> #REF! | U19: =#REF! -> #REF! | V19: =N23 -> #REF! | W19: =S19+T19+U19+V19 -> #REF!
C20: 月累 | N20: =#REF!/#REF!*100 -> #REF! | O20: =J20/J10*100 -> 0 | P20: =K20/K10*100 -> #DIV/0! | Q20: =L20/L10*100 -> 0 | S20: =N16 -> #REF! | T20: =N20 -> #REF! | U20: =#REF! -> #REF! | V20: =N24 -> #REF! | W20: =S20+T20+U20+V20 -> #REF!
B21: 尾矿 | C21: 甲月累 | F21: =F41+'1车间表1'!D24 -> 0 | G21: =IF(ISERROR(J21/F21*100),"0.00",J21/F21*100) -> 0.00 | I21: =IF(ISERROR(L21/F21*1000),"0",L21/F21*1000) -> 0 | J21: =J41+'1车间表1'!I24 -> 0 | L21: =L41+'1车间表1'!K24 -> 0 | N21: =#REF!/#REF!*100 -> #REF! | O21: =J21/J7*100 -> #DIV/0! | P21: =K21/K7*100 -> #DIV/0! | Q21: =L21/L7*100 -> #DIV/0! | S21: =Q13 -> #DIV/0! | T21: =Q17 -> #DIV/0! | U21: =#REF! -> #REF! | V21: =Q21 -> #DIV/0! | W21: =S21+T21+U21+V21 -> #DIV/0!
C22: 乙月累 | F22: =F42+'1车间表1'!D25 -> 117.2601 | G22: =IF(ISERROR(J22/F22*100),"0.00",J22/F22*100) -> 0.13 | I22: =IF(ISERROR(L22/F22*1000),"0",L22/F22*1000) -> -26.766905 | J22: =J42+'1车间表1'!I25 -> 0.15243814 | L22: =L42+'1车间表1'!K25 -> -3.1386901 | N22: =#REF!/#REF!*100 -> #REF! | O22: =J22/J8*100 -> 3.2740149 | P22: =K22/K8*100 -> #DIV/0! | Q22: =L22/L8*100 -> -15.70149 | S22: =Q14 -> 115.70149 | T22: =Q18 -> 0 | U22: =#REF! -> #REF! | V22: =Q22 -> -15.70149 | W22: =S22+T22+U22+V22 -> #REF!
C23: 丙月累 | F23: =F43+'1车间表1'!D26 -> 116.6671 | G23: =IF(ISERROR(J23/F23*100),"0.00",J23/F23*100) -> 0.09 | I23: =IF(ISERROR(L23/F23*1000),"0",L23/F23*1000) -> 27.692432 | J23: =J43+'1车间表1'!I26 -> 0.10500039 | L23: =L43+'1车间表1'!K26 -> 3.2307957 | N23: =#REF!/#REF!*100 -> #REF! | O23: =J23/J9*100 -> 2.0778529 | P23: =K23/K9*100 -> #DIV/0! | Q23: =L23/L9*100 -> 11.313577 | S23: =Q15 -> 88.686423 | T23: =Q19 -> 0 | U23: =#REF! -> #REF! | V23: =Q23 -> 11.313577 | W23: =S23+T23+U23+V23 -> #REF!
C24: 月累 | F24: =F21+F22+F23 -> 233.9272 | G24: =IF(ISERROR(J24/F24*100),"0.00",J24/F24*100) -> 0.1100507 | I24: =IF(ISERROR(L24/F24*1000),"0",L24/F24*1000) -> 0.39373621 | J24: =J21+J22+J23 -> 0.25743853 | L24: =L21+L22+L23 -> 0.092105611 | N24: =#REF!/#REF!*100 -> #REF! | O24: =J24/J10*100 -> 2.65146 | P24: =K24/K10*100 -> #DIV/0! | Q24: =L24/L10*100 -> 0.18972634 | S24: =Q16 -> 99.810274 | T24: =Q20 -> 0 | U24: =#REF! -> #REF! | V24: =Q24 -> 0.18972634 | W24: =S24+T24+U24+V24 -> #REF!
C25: 质检负责人：
D29: 昨日月累：
B30: 种类 | C30: 班别 | D30: 细度％ | E30: 磨矿时间（h） | F30: 干量（T）
G31: 铅（%） | H31: 锌（%） | I31: 银（g/t） | J31: 铅（T） | K31: 锌（T） | L31: 银（Kg）
B32: 原矿 | C32: 一月累
C33: 二月累
C34: 三月累
B35: 铅精 | C35: 一月累
C36: 二月累
C37: 三月累
B38: 锌精 | C38: 一月累
C39: 二月累
C40: 三月累
B41: 尾矿 | C41: 一月累
C42: 二月累
C43: 三月累
D46: 今日月累：
...

Sheet 1车间表3
B2: 选矿厂生产年累统计表 | O2: =(J13+K17)/(J7+K7)*100 -> #DIV/0!
O3: =(J14+K18)/(J8+K8)*100 -> 96.725985
J4: =基础数据!A2 -> 45836 | O4: =(J15+K19)/(J9+K9)*100 -> 97.922147
B5: 种类 | C5: 班别 | D5: 细度％ | E5: 磨矿时间（h） | F5: 干量（T） | G5: 品 位 | J5: 金 属 量 | O5: =(J16+K20)/(J10+K10)*100 -> 97.34854
G6: 铅（%） | H6: 锌（%） | I6: 银（g/t） | J6: 铅（T） | K6: 锌（T） | L6: 银（Kg）
B7: 原矿 | C7: 甲年累 | D7: =IF(ISERROR((D32*F32+'1车间表1'!D7*'1车间表1'!H7)/'1车间表3'!F7),"0.00",(D32*F32+'1车间表1'!D7*'1车间表1'!H7)/'1车间表3'!F7) -> 0.00 | E7: =E32+'1车间表1'!E7 -> 0 | F7: =F32+'1车间表1'!H7 -> 0 | G7: =IF(ISERROR(J7/F7*100),"0.00",J7/F7*100) -> 0.00 | H7: 0.77369581 | I7: =IF(ISERROR(L7/F7*1000),"0.00",L7/F7*1000) -> 0.00 | J7: =J32+'1车间表1'!M7 -> 0 | L7: =L32+'1车间表1'!O7 -> 0 | N7: =D7 -> 0.00 | O7: =F7/E7 -> #DIV/0! | P7: =#REF! -> #REF! | Q7: =G7 -> 0.00 | R7: =H7 -> 0.77369581 | S7: =I7 -> 0.00 | T7: =#REF! -> #REF! | U7: =#REF! -> #REF! | V7: =#REF! -> #REF! | W7: =#REF! -> #REF! | X7: =#REF! -> #REF! | Y7: =G13 -> 0.00 | Z7: =H13 -> 0 | AA7: =I13 -> 0.00 | AB7: =#REF! -> #REF! | AC7: =G17 -> 0 | AD7: =H17 -> 0 | AE7: =I17 -> 0 | AF7: =#REF! -> #REF! | AG7: =G21 -> 0.00 | AH7: =H21 -> 0 | AI7: =I21 -> 0.00 | AJ7: =#REF! -> #REF! | AK7: =D13 -> 0.00 | AL7: =D17 -> 0 | AM7: =E21 -> 0
C8: 乙年累 | D8: =IF(ISERROR((D33*F33+'1车间表1'!D8*'1车间表1'!H8)/'1车间表3'!F8),"0.00",(D33*F33+'1车间表1'!D8*'1车间表1'!H8)/'1车间表3'!F8) -> 0 | E8: =E33+'1车间表1'!E8 -> 8 | F8: =F33+'1车间表1'!H8 -> 124.16 | G8: =IF(ISERROR(J8/F8*100),"0.00",J8/F8*100) -> 3.75 | H8: 0.74011612 | I8: =IF(ISERROR(L8/F8*1000),"0.00",L8/F8*1000) -> 161 | J8: =J33+'1车间表1'!M8 -> 4.656 | L8: =L33+'1车间表1'!O8 -> 19.98976 | N8: =D8 -> 0 | O8: =F8/E8 -> 15.52 | P8: =#REF! -> #REF! | Q8: =G8 -> 3.75 | R8: =H8 -> 0.74011612 | S8: =I8 -> 161 | T8: =#REF! -> #REF! | U8: =#REF! -> #REF! | V8: =#REF! -> #REF! | W8: =#REF! -> #REF! | X8: =#REF! -> #REF! | Y8: =G14 -> 65.27 | Z8: =H14 -> 0 | AA8: =I14 -> 3352 | AB8: =#REF! -> #REF! | AC8: =G18 -> 0 | AD8: =H18 -> 0 | AE8: =I18 -> 0 | AF8: =#REF! -> #REF! | AG8: =G22 -> 0.13 | AH8: =H22 -> 0 | AI8: =I22 -> -26.766905 | AJ8: =#REF! -> #REF! | AK8: =D14 -> 96.725985 | AL8: =D18 -> 0 | AM8: =E22 -> 0
C9: 丙年累 | D9: =IF(ISERROR((D34*F34+'1车间表1'!D9*'1车间表1'!H9)/'1车间表3'!F9),"0.00",(D34*F34+'1车间表1'!D9*'1车间表1'!H9)/'1车间表3'!F9) -> 0 | E9: =E34+'1车间表1'!E9 -> 8 | F9: =F34+'1车间表1'!H9 -> 124.16 | G9: =IF(ISERROR(J9/F9*100),"0.00",J9/F9*100) -> 4.07 | H9: 1.084735 | I9: =IF(ISERROR(L9/F9*1000),"0.00",L9/F9*1000) -> 230 | J9: =J34+'1车间表1'!M9 -> 5.053312 | L9: =L34+'1车间表1'!O9 -> 28.5568 | N9: =D9 -> 0 | O9: =F9/E9 -> 15.52 | P9: =#REF! -> #REF! | Q9: =G9 -> 4.07 | R9: =H9 -> 1.084735 | S9: =I9 -> 230 | T9: =#REF! -> #REF! | U9: =#REF! -> #REF! | V9: =#REF! -> #REF! | W9: =#REF! -> #REF! | X9: =#REF! -> #REF! | Y9: =G15 -> 66.04 | Z9: =H15 -> 0 | AA9: =I15 -> 3380 | AB9: =#REF! -> #REF! | AC9: =G19 -> 0 | AD9: =H19 -> 0 | AE9: =I19 -> 0 | AF9: =#REF! -> #REF! | AG9: =G23 -> 0.09 | AH9: =H23 -> 0 | AI9: =I23 -> 27.692432 | AJ9: =#REF! -> #REF! | AK9: =D15 -> 97.922147 | AL9: =D19 -> 0 | AM9: =E23 -> 0
C10: 年累 | D10: =IF(ISERROR((D7*F7+D8*F8+D9*F9)/F10),"0.00",(D7*F7+D8*F8+D9*F9)/F10) -> 0 | E10: =E7+E8+E9 -> 16 | F10: =F7+F8+F9 -> 248.32 | G10: =IF(ISERROR(J10/F10*100),"0.00",J10/F10*100) -> 3.91 | H10: 0.88694437 | I10: =IF(ISERROR(L10/F10*1000),"0.00",L10/F10*1000) -> 195.5 | J10: =J7+J8+J9 -> 9.709312 | L10: =L7+L8+L9 -> 48.54656 | N10: =D10 -> 0 | O10: =F10/E10 -> 15.52 | P10: =#REF! -> #REF! | Q10: =G10 -> 3.91 | R10: =H10 -> 0.88694437 | S10: =I10 -> 195.5 | T10: =#REF! -> #REF! | U10: =#REF! -> #REF! | V10: =#REF! -> #REF! | W10: =#REF! -> #REF! | X10: =#REF! -> #REF! | Y10: =G16 -> 65.670863 | Z10: =H16 -> 0 | AA10: =I16 -> 3366.5768 | AB10: =#REF! -> #REF! | AC10: =G20 -> 0 | AD10: =H20 -> 0 | AE10: =I20 -> 0 | AF10: =#REF! -> #REF! | AG10: =G24 -> 0.1100507 | AH10: =H24 -> 0 | AI10: =I24 -> 0.39373621 | AJ10: =#REF! -> #REF! | AK10: =D16 -> 97.34854 | AL10: =D20 -> 0 | AM10: =E24 -> 0
B11: 种类 | C11: 班别 | D11: 回收率（%） | F11: 干量（T） | G11: 分 布 率 | J11: 金 属 量
D12: 铜铅锌 | E12: 银 | G12: 铅（%） | H12: 锌（%） | I12: 银（g/t） | J12: 铅（T） | K12: 锌（T） | L12: 银（Kg）
B13: 铅精 | C13: 甲年累 | D13: =IF(ISERROR(J13/J7*100),"0.00",J13/J7*100) -> 0.00 | E13: =IF(ISERROR(L13/L7*100),"0.00",L13/L7*100) -> 0.00 | F13: =F35+'1车间表1'!D14 -> 0 | G13: =IF(ISERROR(J13/F13*100),"0.00",J13/F13*100) -> 0.00 | I13: =IF(ISERROR(L13/F13*1000),"0.00",L13/F13*1000) -> 0.00 | J13: =J35+'1车间表1'!I14 -> 0 | L13: =L35+'1车间表1'!K14 -> 0 | N13: =#REF!/#REF!*100 -> #REF! | O13: =J13/J7*100 -> #DIV/0! | P13: =K13/K7*100 -> #DIV/0! | Q13: =L13/L7*100 -> #DIV/0! | S13: =P13 -> #DIV/0! | T13: =P17 -> #DIV/0! | U13: =#REF! -> #REF! | V13: =P21 -> #DIV/0! | W13: =S13+T13+U13+V13 -> #DIV/0!
C14: 乙年累 | D14: =IF(ISERROR(J14/J8*100),"0.00",J14/J8*100) -> 96.725985 | E14: =IF(ISERROR(L14/L8*100),"0.00",L14/L8*100) -> 115.70149 | F14: =F36+'1车间表1'!D15 -> 6.8998956 | G14: =IF(ISERROR(J14/F14*100),"0.00",J14/F14*100) -> 65.27 | I14: =IF(ISERROR(L14/F14*1000),"0.00",L14/F14*1000) -> 3352 | J14: =J36+'1车间表1'!I15 -> 4.5035619 | L14: =L36+'1车间表1'!K15 -> 23.12845 | N14: =#REF!/#REF!*100 -> #REF! | O14: =J14/J8*100 -> 96.725985 | P14: =K14/K8*100 -> #DIV/0! | Q14: =L14/L8*100 -> 115.70149 | S14: =P14 -> #DIV/0! | T14: =P18 -> #DIV/0! | U14: =#REF! -> #REF! | V14: =P22 -> #DIV/0! | W14: =S14+T14+U14+V14 -> #DIV/0!
C15: 丙年累 | D15: =IF(ISERROR(J15/J9*100),"0.00",J15/J9*100) -> 97.922147 | E15: =IF(ISERROR(L15/L9*100),"0.00",L15/L9*100) -> 88.686423 | F15: =F37+'1车间表1'!D16 -> 7.4929007 | G15: =IF(ISERROR(J15/F15*100),"0.00",J15/F15*100) -> 66.04 | I15: =IF(ISERROR(L15/F15*1000),"0.00",L15/F15*1000) -> 3380 | J15: =J37+'1车间表1'!I16 -> 4.9483116 | L15: =L37+'1车间表1'!K16 -> 25.326004 | N15: =#REF!/#REF!*100 -> #REF! | O15: =J15/J9*100 -> 97.922147 | P15: =K15/K9*100 -> #DIV/0! | Q15: =L15/L9*100 -> 88.686423 | S15: =P15 -> #DIV/0! | T15: =P19 -> #DIV/0! | U15: =#REF! -> #REF! | V15: =P23 -> #DIV/0! | W15: =S15+T15+U15+V15 -> #DIV/0!
C16: 年累 | D16: =IF(ISERROR(J16/J10*100),"0.00",J16/J10*100) -> 97.34854 | E16: =IF(ISERROR(L16/L10*100),"0.00",L16/L10*100) -> 99.810274 | F16: =F13+F14+F15 -> 14.392796 | G16: =IF(ISERROR(J16/F16*100),"0.00",J16/F16*100) -> 65.670863 | I16: =IF(ISERROR(L16/F16*1000),"0.00",L16/F16*1000) -> 3366.5768 | J16: =J13+J14+J15 -> 9.4518735 | L16: =L13+L14+L15 -> 48.454454 | N16: =#REF!/#REF!*100 -> #REF! | O16: =J16/J10*100 -> 97.34854 | P16: =K16/K10*100 -> #DIV/0! | Q16: =L16/L10*100 -> 99.810274 | S16: =P16 -> #DIV/0! | T16: =P20 -> #DIV/0! | U16: =#REF! -> #REF! | V16: =P24 -> #DIV/0! | W16: =S16+T16+U16+V16 -> #DIV/0!
B17: 锌精 | C17: 甲年累 | N17: =#REF!/#REF!*100 -> #REF! | O17: =J17/J7*100 -> #DIV/0! | P17: =K17/K7*100 -> #DIV/0! | Q17: =L17/L7*100 -> #DIV/0! | S17: =N13 -> #REF! | T17: =N17 -> #REF! | U17: =#REF! -> #REF! | V17: =N21 -> #REF! | W17: =S17+T17+U17+V17 -> #REF!
C18: 乙年累 | N18: =#REF!/#REF!*100 -> #REF! | O18: =J18/J8*100 -> 0 | P18: =K18/K8*100 -> #DIV/0! | Q18: =L18/L8*100 -> 0 | S18: =N14 -> #REF! | T18: =N18 -> #REF! | U18: =#REF! -> #REF! | V18: =N22 -> #REF! | W18: =S18+T18+U18+V18 -> #REF!
C19: 丙年累 | N19: =#REF!/#REF!*100 -> #REF! | O19: =J19/J9*100 -> 0 | P19: =K19/K9*100 -> #DIV/0! | Q19: =L19/L9*100 -> 0 | S19: =N15 -> #REF! | T19: =N19 -> #REF! | U19: =#REF! -> #REF! | V19: =N23 -> #REF! | W19: =S19+T19+U19+V19 -> #REF!
C20: 年累 | N20: =#REF!/#REF!*100 -> #REF! | O20: =J20/J10*100 -> 0 | P20: =K20/K10*100 -> #DIV/0! | Q20: =L20/L10*100 -> 0 | S20: =N16 -> #REF! | T20: =N20 -> #REF! | U20: =#REF! -> #REF! | V20: =N24 -> #REF! | W20: =S20+T20+U20+V20 -> #REF!
B21: 尾矿 | C21: 甲年累 | F21: =F41+'1车间表1'!D24 -> 0 | G21: =IF(ISERROR(J21/F21*100),"0.00",J21/F21*100) -> 0.00 | I21: =IF(ISERROR(L21/F21*1000),"0.00",L21/F21*1000) -> 0.00 | J21: =J41+'1车间表1'!I24 -> 0 | L21: =L41+'1车间表1'!K24 -> 0 | N21: =#REF!/#REF!*100 -> #REF! | O21: =J21/J7*100 -> #DIV/0! | P21: =K21/K7*100 -> #DIV/0! | Q21: =L21/L7*100 -> #DIV/0! | S21: =Q13 -> #DIV/0! | T21: =Q17 -> #DIV/0! | U21: =#REF! -> #REF! | V21: =Q21 -> #DIV/0! | W21: =S21+T21+U21+V21 -> #DIV/0!
C22: 乙年累 | F22: =F42+'1车间表1'!D25 -> 117.2601 | G22: =IF(ISERROR(J22/F22*100),"0.00",J22/F22*100) -> 0.13 | I22: =IF(ISERROR(L22/F22*1000),"0.00",L22/F22*1000) -> -26.766905 | J22: =J42+'1车间表1'!I25 -> 0.15243814 | L22: =L42+'1车间表1'!K25 -> -3.1386901 | N22: =#REF!/#REF!*100 -> #REF! | O22: =J22/J8*100 -> 3.2740149 | P22: =K22/K8*100 -> #DIV/0! | Q22: =L22/L8*100 -> -15.70149 | S22: =Q14 -> 115.70149 | T22: =Q18 -> 0 | U22: =#REF! -> #REF! | V22: =Q22 -> -15.70149 | W22: =S22+T22+U22+V22 -> #REF!
C23: 丙年累 | F23: =F43+'1车间表1'!D26 -> 116.6671 | G23: =IF(ISERROR(J23/F23*100),"0.00",J23/F23*100) -> 0.09 | I23: =IF(ISERROR(L23/F23*1000),"0.00",L23/F23*1000) -> 27.692432 | J23: =J43+'1车间表1'!I26 -> 0.10500039 | L23: =L43+'1车间表1'!K26 -> 3.2307957 | N23: =#REF!/#REF!*100 -> #REF! | O23: =J23/J9*100 -> 2.0778529 | P23: =K23/K9*100 -> #DIV/0! | Q23: =L23/L9*100 -> 11.313577 | S23: =Q15 -> 88.686423 | T23: =Q19 -> 0 | U23: =#REF! -> #REF! | V23: =Q23 -> 11.313577 | W23: =S23+T23+U23+V23 -> #REF!
C24: 年累 | F24: =F21+F22+F23 -> 233.9272 | G24: =IF(ISERROR(J24/F24*100),"0.00",J24/F24*100) -> 0.1100507 | I24: =IF(ISERROR(L24/F24*1000),"0.00",L24/F24*1000) -> 0.39373621 | J24: =J21+J22+J23 -> 0.25743853 | L24: =L21+L22+L23 -> 0.092105611 | N24: =#REF!/#REF!*100 -> #REF! | O24: =J24/J10*100 -> 2.65146 | P24: =K24/K10*100 -> #DIV/0! | Q24: =L24/L10*100 -> 0.18972634 | S24: =Q16 -> 99.810274 | T24: =Q20 -> 0 | U24: =#REF! -> #REF! | V24: =Q24 -> 0.18972634 | W24: =S24+T24+U24+V24 -> #REF!
C25: 质检负责人：
D29: 昨日年累：
B30: 种类 | C30: 班别 | D30: 细度％ | E30: 磨矿时间（h） | F30: 干量（T）
G31: 铅（%） | H31: 锌（%） | I31: 银（g/t） | J31: 铅（T） | K31: 锌（T） | L31: 银（Kg）
B32: 原矿 | C32: （一）累
C33: （二）累
C34: （三）累
B35: 铅精 | C35: （一）累
C36: （二）累
C37: （三）累
B38: 锌精 | C38: （一）累
C39: （二）累
C40: （三）累
B41: 尾矿 | C41: （一）累
C42: （二）累
C43: （三）累
D46: 今日年累：
...

Sheet 1系统周表
B2: 荣达选矿厂隆腾矿生产日报一系统(周表） | O2: =(J13+K17)/(J7+K7)*100 -> 97.308219
O3: =(J14+K18)/(J8+K8)*100 -> 96.725985
J4: =基础数据!A2 -> 45836 | O4: =(J15+K19)/(J9+K9)*100 -> 97.922147
B5: 种类 | C5: 班别 | D5: 细度％ | E5: 磨矿时间（h） | F5: 干量（T） | O5: =(J16+K20)/(J10+K10)*100 -> 97.312632
G6: 铅（%） | H6: 锌（%） | I6: 银（g/t） | J6: 铅（T） | K6: 锌（T） | L6: 银（Kg）
B7: 原矿 | C7: 甲周累 | D7: =IF(ISERROR((D32*F32+'1车间表1'!D7*'1车间表1'!H7)/'1系统周表'!F7),"0.00",(D32*F32+'1车间表1'!D7*'1车间表1'!H7)/'1系统周表'!F7) -> 45.6 | E7: =E32+'1车间表1'!E7 -> 9 | F7: =F32+'1车间表1'!H7 -> 752.39671 | G7: =IF(ISERROR(J7/F7*100),"0.00",J7/F7*100) -> 10.5 | I7: =IF(ISERROR(L7/F7*1000),"0.00",L7/F7*1000) -> 570 | J7: =J32+'1车间表1'!M7 -> 79.001655 | L7: =L32+'1车间表1'!O7 -> 428.86613 | N7: =D7 -> 45.6 | O7: =F7/E7 -> 83.599635 | P7: =#REF! -> #REF! | Q7: =G7 -> 10.5 | R7: =H7 -> 0 | S7: =I7 -> 570 | T7: =#REF! -> #REF! | U7: =#REF! -> #REF! | V7: =#REF! -> #REF! | W7: =#REF! -> #REF! | X7: =#REF! -> #REF! | Y7: =G13 -> 60.56 | Z7: =H13 -> 0 | AA7: =I13 -> 3299 | AB7: =#REF! -> #REF! | AC7: =G17 -> 0 | AD7: =H17 -> 0 | AE7: =I17 -> 0 | AF7: =#REF! -> #REF! | AG7: =G21 -> 0.34 | AH7: =H21 -> 0 | AI7: =I21 -> 16.131842 | AJ7: =#REF! -> #REF! | AK7: =D13 -> 97.308219 | AL7: =D17 -> 0 | AM7: =E21 -> 0
C8: 乙周累 | D8: =IF(ISERROR((D33*F33+'1车间表1'!D8*'1车间表1'!H8)/'1系统周表'!F8),"0.00",(D33*F33+'1车间表1'!D8*'1车间表1'!H8)/'1系统周表'!F8) -> 0 | E8: =E33+'1车间表1'!E8 -> 8 | F8: =F33+'1车间表1'!H8 -> 124.16 | G8: =IF(ISERROR(J8/F8*100),"0.00",J8/F8*100) -> 3.75 | I8: =IF(ISERROR(L8/F8*1000),"0.00",L8/F8*1000) -> 161 | J8: =J33+'1车间表1'!M8 -> 4.656 | L8: =L33+'1车间表1'!O8 -> 19.98976 | N8: =D8 -> 0 | O8: =F8/E8 -> 15.52 | P8: =#REF! -> #REF! | Q8: =G8 -> 3.75 | R8: =H8 -> 0 | S8: =I8 -> 161 | T8: =#REF! -> #REF! | U8: =#REF! -> #REF! | V8: =#REF! -> #REF! | W8: =#REF! -> #REF! | X8: =#REF! -> #REF! | Y8: =G14 -> 65.27 | Z8: =H14 -> 0 | AA8: =I14 -> 3352 | AB8: =#REF! -> #REF! | AC8: =G18 -> 0 | AD8: =H18 -> 0 | AE8: =I18 -> 0 | AF8: =#REF! -> #REF! | AG8: =G22 -> 0.13 | AH8: =H22 -> 0 | AI8: =I22 -> -26.766905 | AJ8: =#REF! -> #REF! | AK8: =D14 -> 96.725985 | AL8: =D18 -> 0 | AM8: =E22 -> 0
C9: 丙周累 | D9: =IF(ISERROR((D34*F34+'1车间表1'!D9*'1车间表1'!H9)/'1系统周表'!F9),"0.00",(D34*F34+'1车间表1'!D9*'1车间表1'!H9)/'1系统周表'!F9) -> 0 | E9: =E34+'1车间表1'!E9 -> 8 | F9: =F34+'1车间表1'!H9 -> 124.16 | G9: =IF(ISERROR(J9/F9*100),"0.00",J9/F9*100) -> 4.07 | I9: =IF(ISERROR(L9/F9*1000),"0.00",L9/F9*1000) -> 230 | J9: =J34+'1车间表1'!M9 -> 5.053312 | L9: =L34+'1车间表1'!O9 -> 28.5568 | N9: =D9 -> 0 | O9: =F9/E9 -> 15.52 | P9: =#REF! -> #REF! | Q9: =G9 -> 4.07 | R9: =H9 -> 0 | S9: =I9 -> 230 | T9: =#REF! -> #REF! | U9: =#REF! -> #REF! | V9: =#REF! -> #REF! | W9: =#REF! -> #REF! | X9: =#REF! -> #REF! | Y9: =G15 -> 66.04 | Z9: =H15 -> 0 | AA9: =I15 -> 3380 | AB9: =#REF! -> #REF! | AC9: =G19 -> 0 | AD9: =H19 -> 0 | AE9: =I19 -> 0 | AF9: =#REF! -> #REF! | AG9: =G23 -> 0.09 | AH9: =H23 -> 0 | AI9: =I23 -> 27.692432 | AJ9: =#REF! -> #REF! | AK9: =D15 -> 97.922147 | AL9: =D19 -> 0 | AM9: =E23 -> 0
C10: 周累 | D10: =IF(ISERROR((D7*F7+D8*F8+D9*F9)/F10),"0.00",(D7*F7+D8*F8+D9*F9)/F10) -> 34.284718 | E10: =E7+E8+E9 -> 25 | F10: =F7+F8+F9 -> 1000.7167 | G10: =IF(ISERROR(J10/F10*100),"0.00",J10/F10*100) -> 8.8647432 | I10: =IF(ISERROR(L10/F10*1000),"0.00",L10/F10*1000) -> 477.07076 | J10: =J7+J8+J9 -> 88.710967 | L10: =L7+L8+L9 -> 477.41269 | N10: =D10 -> 34.284718 | O10: =F10/E10 -> 40.028669 | P10: =#REF! -> #REF! | Q10: =G10 -> 8.8647432 | R10: =H10 -> 0 | S10: =I10 -> 477.07076 | T10: =#REF! -> #REF! | U10: =#REF! -> #REF! | V10: =#REF! -> #REF! | W10: =#REF! -> #REF! | X10: =#REF! -> #REF! | Y10: =G16 -> 61.080469 | Z10: =H16 -> 0 | AA10: =I16 -> 3305.8817 | AB10: =#REF! -> #REF! | AC10: =G20 -> 0 | AD10: =H20 -> 0 | AE10: =I20 -> 0 | AF10: =#REF! -> #REF! | AG10: =G24 -> 0.277407 | AH10: =H24 -> 0 | AI10: =I24 -> 11.847874 | AJ10: =#REF! -> #REF! | AK10: =D16 -> 97.312632 | AL10: =D20 -> 0 | AM10: =E24 -> 0
B11: 种类 | C11: 班别 | D11: 回收率（%） | F11: 干量（T）
D12: 铜铅锌 | E12: 银 | G12: 铅（%） | I12: 银（g/t） | J12: 铅（T） | K12: 锌（T） | L12: 银（Kg）
B13: 铅精 | C13: 甲周累 | D13: =IF(ISERROR(J13/J7*100),"0.00",J13/J7*100) -> 97.308219 | E13: =IF(ISERROR(L13/L7*100),"0.00",L13/L7*100) -> 97.64734 | F13: =F35+'1车间表1'!D14 -> 126.9404 | G13: =IF(ISERROR(J13/F13*100),"0.00",J13/F13*100) -> 60.56 | I13: =IF(ISERROR(L13/F13*1000),"0.00",L13/F13*1000) -> 3299 | J13: =J35+'1车间表1'!I14 -> 76.875103 | L13: =L35+'1车间表1'!K14 -> 418.77636 | N13: =#REF!/#REF!*100 -> #REF! | O13: =J13/J7*100 -> 97.308219 | P13: =K13/K7*100 -> #DIV/0! | Q13: =L13/L7*100 -> 97.64734 | S13: =P13 -> #DIV/0! | T13: =P17 -> #DIV/0! | U13: =#REF! -> #REF! | V13: =P21 -> #DIV/0! | W13: =S13+T13+U13+V13 -> #DIV/0!
C14: 乙周累 | D14: =IF(ISERROR(J14/J8*100),"0.00",J14/J8*100) -> 96.725985 | E14: =IF(ISERROR(L14/L8*100),"0.00",L14/L8*100) -> 115.70149 | F14: =F36+'1车间表1'!D15 -> 6.8998956 | G14: =IF(ISERROR(J14/F14*100),"0.00",J14/F14*100) -> 65.27 | I14: =IF(ISERROR(L14/F14*1000),"0.00",L14/F14*1000) -> 3352 | J14: =J36+'1车间表1'!I15 -> 4.5035619 | L14: =L36+'1车间表1'!K15 -> 23.12845 | N14: =#REF!/#REF!*100 -> #REF! | O14: =J14/J8*100 -> 96.725985 | P14: =K14/K8*100 -> #DIV/0! | Q14: =L14/L8*100 -> 115.70149 | S14: =P14 -> #DIV/0! | T14: =P18 -> #DIV/0! | U14: =#REF! -> #REF! | V14: =P22 -> #DIV/0! | W14: =S14+T14+U14+V14 -> #DIV/0!
C15: 丙周累 | D15: =IF(ISERROR(J15/J9*100),"0.00",J15/J9*100) -> 97.922147 | E15: =IF(ISERROR(L15/L9*100),"0.00",L15/L9*100) -> 88.686423 | F15: =F37+'1车间表1'!D16 -> 7.4929007 | G15: =IF(ISERROR(J15/F15*100),"0.00",J15/F15*100) -> 66.04 | I15: =IF(ISERROR(L15/F15*1000),"0.00",L15/F15*1000) -> 3380 | J15: =J37+'1车间表1'!I16 -> 4.9483116 | L15: =L37+'1车间表1'!K16 -> 25.326004 | N15: =#REF!/#REF!*100 -> #REF! | O15: =J15/J9*100 -> 97.922147 | P15: =K15/K9*100 -> #DIV/0! | Q15: =L15/L9*100 -> 88.686423 | S15: =P15 -> #DIV/0! | T15: =P19 -> #DIV/0! | U15: =#REF! -> #REF! | V15: =P23 -> #DIV/0! | W15: =S15+T15+U15+V15 -> #DIV/0!
C16: 周累 | D16: =IF(ISERROR(J16/J10*100),"0.00",J16/J10*100) -> 97.312632 | E16: =IF(ISERROR(L16/L10*100),"0.00",L16/L10*100) -> 97.867282 | F16: =F13+F14+F15 -> 141.33319 | G16: =IF(ISERROR(J16/F16*100),"0.00",J16/F16*100) -> 61.080469 | I16: =IF(ISERROR(L16/F16*1000),"0.00",L16/F16*1000) -> 3305.8817 | J16: =J13+J14+J15 -> 86.326977 | L16: =L13+L14+L15 -> 467.23082 | N16: =#REF!/#REF!*100 -> #REF! | O16: =J16/J10*100 -> 97.312632 | P16: =K16/K10*100 -> #DIV/0! | Q16: =L16/L10*100 -> 97.867282 | S16: =P16 -> #DIV/0! | T16: =P20 -> #DIV/0! | U16: =#REF! -> #REF! | V16: =P24 -> #DIV/0! | W16: =S16+T16+U16+V16 -> #DIV/0!
B17: 锌精 | C17: 甲周累 | N17: =#REF!/#REF!*100 -> #REF! | O17: =J17/J7*100 -> 0 | P17: =K17/K7*100 -> #DIV/0! | Q17: =L17/L7*100 -> 0 | S17: =N13 -> #REF! | T17: =N17 -> #REF! | U17: =#REF! -> #REF! | V17: =N21 -> #REF! | W17: =S17+T17+U17+V17 -> #REF!
C18: 乙周累 | N18: =#REF!/#REF!*100 -> #REF! | O18: =J18/J8*100 -> 0 | P18: =K18/K8*100 -> #DIV/0! | Q18: =L18/L8*100 -> 0 | S18: =N14 -> #REF! | T18: =N18 -> #REF! | U18: =#REF! -> #REF! | V18: =N22 -> #REF! | W18: =S18+T18+U18+V18 -> #REF!
C19: 丙周累 | N19: =#REF!/#REF!*100 -> #REF! | O19: =J19/J9*100 -> 0 | P19: =K19/K9*100 -> #DIV/0! | Q19: =L19/L9*100 -> 0 | S19: =N15 -> #REF! | T19: =N19 -> #REF! | U19: =#REF! -> #REF! | V19: =N23 -> #REF! | W19: =S19+T19+U19+V19 -> #REF!
C20: 周累 | N20: =#REF!/#REF!*100 -> #REF! | O20: =J20/J10*100 -> 0 | P20: =K20/K10*100 -> #DIV/0! | Q20: =L20/L10*100 -> 0 | S20: =N16 -> #REF! | T20: =N20 -> #REF! | U20: =#REF! -> #REF! | V20: =N24 -> #REF! | W20: =S20+T20+U20+V20 -> #REF!
B21: 尾矿 | C21: 甲周累 | F21: =F41+'1车间表1'!D24 -> 625.45632 | G21: =IF(ISERROR(J21/F21*100),"0.00",J21/F21*100) -> 0.34 | I21: =IF(ISERROR(L21/F21*1000),"0.00",L21/F21*1000) -> 16.131842 | J21: =J41+'1车间表1'!I24 -> 2.1265515 | L21: =L41+'1车间表1'!K24 -> 10.089762 | N21: =#REF!/#REF!*100 -> #REF! | O21: =J21/J7*100 -> 2.6917809 | P21: =K21/K7*100 -> #DIV/0! | Q21: =L21/L7*100 -> 2.3526601 | S21: =Q13 -> 97.64734 | T21: =Q17 -> 0 | U21: =#REF! -> #REF! | V21: =Q21 -> 2.3526601 | W21: =S21+T21+U21+V21 -> #REF!
C22: 乙周累 | F22: =F42+'1车间表1'!D25 -> 117.2601 | G22: =IF(ISERROR(J22/F22*100),"0.00",J22/F22*100) -> 0.13 | I22: =IF(ISERROR(L22/F22*1000),"0.00",L22/F22*1000) -> -26.766905 | J22: =J42+'1车间表1'!I25 -> 0.15243814 | L22: =L42+'1车间表1'!K25 -> -3.1386901 | N22: =#REF!/#REF!*100 -> #REF! | O22: =J22/J8*100 -> 3.2740149 | P22: =K22/K8*100 -> #DIV/0! | Q22: =L22/L8*100 -> -15.70149 | S22: =Q14 -> 115.70149 | T22: =Q18 -> 0 | U22: =#REF! -> #REF! | V22: =Q22 -> -15.70149 | W22: =S22+T22+U22+V22 -> #REF!
C23: 丙周累 | F23: =F43+'1车间表1'!D26 -> 116.6671 | G23: =IF(ISERROR(J23/F23*100),"0.00",J23/F23*100) -> 0.09 | I23: =IF(ISERROR(L23/F23*1000),"0.00",L23/F23*1000) -> 27.692432 | J23: =J43+'1车间表1'!I26 -> 0.10500039 | L23: =L43+'1车间表1'!K26 -> 3.2307957 | N23: =#REF!/#REF!*100 -> #REF! | O23: =J23/J9*100 -> 2.0778529 | P23: =K23/K9*100 -> #DIV/0! | Q23: =L23/L9*100 -> 11.313577 | S23: =Q15 -> 88.686423 | T23: =Q19 -> 0 | U23: =#REF! -> #REF! | V23: =Q23 -> 11.313577 | W23: =S23+T23+U23+V23 -> #REF!
C24: 周累 | F24: =F21+F22+F23 -> 859.38352 | G24: =IF(ISERROR(J24/F24*100),"0.00",J24/F24*100) -> 0.277407 | I24: =IF(ISERROR(L24/F24*1000),"0.00",L24/F24*1000) -> 11.847874 | J24: =J21+J22+J23 -> 2.38399 | L24: =L21+L22+L23 -> 10.181868 | N24: =#REF!/#REF!*100 -> #REF! | O24: =J24/J10*100 -> 2.6873679 | P24: =K24/K10*100 -> #DIV/0! | Q24: =L24/L10*100 -> 2.1327184 | S24: =Q16 -> 97.867282 | T24: =Q20 -> 0 | U24: =#REF! -> #REF! | V24: =Q24 -> 2.1327184 | W24: =S24+T24+U24+V24 -> #REF!
C25: 质检负责人：
D29: 昨日周累：
B30: 种类 | C30: 班别 | D30: 细度％ | E30: 磨矿时间（h） | F30: 干量（T）
G31: 铅（%） | H31: 锌（%） | I31: 银（g/t） | J31: 铅（T） | K31: 锌（T） | L31: 银（Kg）
B32: 原矿 | C32: （一）累 | D32: 45.6 | E32: 9 | F32: 752.39671 | J32: 79.001655 | K32: 0 | L32: 428.86613
C33: （二）累 | D33: 0.00 | E33: 0 | F33: 0 | J33: 0 | K33: 0 | L33: 0
C34: （三）累 | D34: 0.00 | E34: 0 | F34: 0 | J34: 0 | K34: 0 | L34: 0
B35: 铅精 | C35: （一）累 | F35: 126.9404 | J35: 76.875103 | K35: 0 | L35: 418.77636
C36: （二）累 | F36: 0 | J36: 0 | K36: 0 | L36: 0
C37: （三）累 | F37: 0 | J37: 0 | K37: 0 | L37: 0
B38: 锌精 | C38: （一）累 | F38: 0 | J38: 0 | K38: 0 | L38: 0
C39: （二）累 | F39: 0 | J39: 0 | K39: 0 | L39: 0
C40: （三）累 | F40: 0 | J40: 0 | K40: 0 | L40: 0
B41: 尾矿 | C41: （一）累 | F41: 625.45632 | J41: 2.1265515 | K41: 0 | L41: 10.089762
C42: （二）累 | F42: 0 | J42: 0 | K42: 0 | L42: 0
C43: （三）累 | F43: 0 | J43: 0 | K43: 0 | L43: 0
D46: 今日周累：
...

Sheet 2车间表1
B2: 荣达选矿厂生产隆腾矿日报表（金属平衡表）
M4: =基础数据!A2 -> 45836
B5: 种类 | C5: 班别 | D5: 细度％ | E5: 磨矿时间（h） | F5: 处 理 量 | I5: 品 位 | L5: 金 属 量
F6: 湿量（T） | G6: 水份（%） | H6: 干量（T） | I6: 铅（%） | J6: 锌（%） | K6: 银（g/t） | L6: 铜（T） | M6: 铅（T） | N6: 锌（T） | O6: 银（Kg）
B7: 原矿 | C7: A | D7: =基础数据!N7 -> 0 | E7: =基础数据!N5 -> 0 | F7: =基础数据!N6 -> 0 | G7: =基础数据!N9 -> 0 | H7: =F7*(1-G7%) -> 0 | I7: =基础数据!J5 -> 0 | K7: =基础数据!L5 -> 0 | M7: =H7*I7/100 -> 0 | O7: =H7*K7/1000 -> 0
C8: B | D8: =基础数据!N19 -> 0 | E8: =基础数据!N17 -> 0 | F8: =基础数据!N18 -> 0 | G8: =基础数据!N21 -> 0 | H8: =F8*(1-G8%) -> 0 | I8: =基础数据!J17 -> 0 | K8: =基础数据!L17 -> 0 | M8: =H8*I8/100 -> 0 | O8: =H8*K8/1000 -> 0
C9: C | D9: =基础数据!N31 -> 0 | E9: =基础数据!N29 -> 0 | F9: =基础数据!N30 -> 0 | G9: =基础数据!N33 -> 0 | H9: =F9*(1-G9%) -> 0 | I9: =基础数据!J29 -> 0 | K9: =基础数据!L29 -> 0 | M9: =H9*I9/100 -> 0 | O9: =H9*K9/1000 -> 0
C10: 日累 | D10: =IF(ISERROR((D7*H7+D8*H8+D9*H9)/(H7+H8+H9)),"0.00",(D7*H7+D8*H8+D9*H9)/(H7+H8+H9)) -> 0.00 | E10: =E7+E8+E9 -> 0 | F10: =F7+F8+F9 -> 0 | G10: =IF(ISERROR((F10-H10)/F10*100),"0.00",(F10-H10)/F10*100) -> 0.00 | H10: =H7+H8+H9 -> 0 | I10: =IF(ISERROR(M10/H10*100),"0.00",M10/H10*100) -> 0.00 | K10: =IF(ISERROR(O10/H10*1000),"0",O10/H10*1000) -> 0 | M10: =M7+M8+M9 -> 0 | O10: =O7+O8+O9 -> 0
C11: 月累 | D11: =IF(ISERROR((D35*H35+H10*D10)/H11),"0.00",(D35*H35+H10*D10)/H11) -> 0.00 | E11: =E10+E35 -> 0 | F11: =F10+F35 -> 0 | G11: =IF(ISERROR((F11-H11)/F11*100),"0.00",(F11-H11)/F11*100) -> 0.00 | H11: =H10+H35 -> 0 | I11: =IF(ISERROR(M11/H11*100),"0.00",M11/H11*100) -> 0.00 | K11: =IF(ISERROR(O11/H11*1000),"0",O11/H11*1000) -> 0 | M11: =M10+M35 -> 0 | O11: =O10+O35 -> 0
B12: 种类 | C12: 班别 | D12: 干量（T） | E12: 分 布 率 | I12: 金 属 量 | L12: 回收率（%） | N12: 产率（%） | O12: 富集比
E13: 铜（%） | F13: 铅（%） | G13: 锌（%） | H13: 银（g/t） | I13: 铅（T） | J13: 锌（T） | K13: 银（Kg） | L13: 铜铅锌 | M13: 银
B14: 铅精矿 | C14: A | D14: =N14*H7/100 -> 0 | F14: =基础数据!J11 -> 0 | H14: =基础数据!L11 -> 0 | I14: =D14*F14/100 -> 0 | K14: =D14*H14/1000 -> 0 | L14: =O14*N14 -> 0 | M14: =IF(ISERROR(H14/K7*N14),"0.00",H14/K7*N14) -> 0.00 | N14: =IF(ISERROR(S14/T14),"0.00",S14/T14) -> 0.00 | O14: =IF(ISERROR(F14/I7),"0.00",F14/I7) -> 0.00 | S14: =(I7-F24)*100 -> 0 | T14: =F14-F24 -> 0
C15: B | D15: =N15*H8/100 -> 0 | F15: =基础数据!J23 -> 0 | H15: =基础数据!L23 -> 0 | I15: =D15*F15/100 -> 0 | K15: =D15*H15/1000 -> 0 | L15: =O15*N15 -> 0 | M15: =IF(ISERROR(H15/K8*N15),"0.00",H15/K8*N15) -> 0.00 | N15: =IF(ISERROR(S15/T15),"0.00",S15/T15) -> 0.00 | O15: =IF(ISERROR(F15/I8),"0.00",F15/I8) -> 0.00 | S15: =(I8-F25)*100 -> 0 | T15: =F15-F25 -> 0
C16: C | D16: =N16*H9/100 -> 0 | F16: =基础数据!J35 -> 0 | H16: =基础数据!L35 -> 0 | I16: =D16*F16/100 -> 0 | K16: =D16*H16/1000 -> 0 | L16: =O16*N16 -> 0 | M16: =IF(ISERROR(H16/K9*N16),"0.00",H16/K9*N16) -> 0.00 | N16: =IF(ISERROR(S16/T16),"0.00",S16/T16) -> 0.00 | O16: =IF(ISERROR(F16/I9),"0.00",F16/I9) -> 0.00 | S16: =(I9-F26)*100 -> 0 | T16: =F16-F26 -> 0
C17: 日累 | D17: =D14+D15+D16 -> 0 | F17: =IF(ISERROR(I17/D17*100),"0.00",I17/D17*100) -> 0.00 | H17: =IF(ISERROR(K17/D17*1000),"0",K17/D17*1000) -> 0 | I17: =I14+I15+I16 -> 0 | K17: =K14+K15+K16 -> 0 | L17: =IF(ISERROR(I17/M10*100),"0.00",I17/M10*100) -> 0.00 | M17: =IF(ISERROR(K17/O10*100),"0.00",K17/O10*100) -> 0.00 | N17: =IF(ISERROR(L17/O17),"0.00",L17/O17) -> 0.00 | O17: =IF(ISERROR(F17/I10),"0.00",F17/I10) -> 0.00
C18: 月累 | D18: =D17+D36 -> 0 | F18: =IF(ISERROR(I18/D18*100),"0.00",I18/D18*100) -> 0.00 | H18: =IF(ISERROR(K18/D18*1000),"0",K18/D18*1000) -> 0 | I18: =I17+I36 -> 0 | K18: =K17+K36 -> 0 | L18: =IF(ISERROR(I18/M11*100),"0.00",I18/M11*100) -> 0.00 | M18: =IF(ISERROR(K18/O11*100),"0.00",K18/O11*100) -> 0.00 | N18: =IF(ISERROR(L18/O18),"0.00",L18/O18) -> 0.00 | O18: =IF(ISERROR(F18/I11),"0.00",F18/I11) -> 0.00
B19: 锌精矿 | C19: A
C20: B
C21: C
C22: 日累
C23: 月累
B24: 尾矿 | C24: A | D24: =H7-D14-D19 -> 0 | F24: =基础数据!J13 -> 0 | H24: =基础数据!L13 -> 0 | I24: =M7-I14-I19 -> 0 | K24: =O7-K14-K19 -> 0
C25: B | D25: =H8-D15-D20 -> 0 | F25: =基础数据!J25 -> 0 | H25: =基础数据!L25 -> 0 | I25: =M8-I15-I20 -> 0 | K25: =O8-K15-K20 -> 0
C26: C | D26: =H9-D16-D21 -> 0 | F26: =基础数据!J37 -> 0 | H26: =基础数据!L37 -> 0 | I26: =M9-I16-I21 -> 0 | K26: =O9-K16-K21 -> 0
C27: 日累 | D27: =D24+D25+D26 -> 0 | F27: =IF(ISERROR(I27/D27*100),"0.00",I27/D27*100) -> 0.00 | H27: =IF(ISERROR(K27/D27*1000),"0",K27/D27*1000) -> 0 | I27: =I24+I25+I26 -> 0 | K27: =K24+K25+K26 -> 0
C28: 月累 | D28: =D27+D38 -> 0 | F28: =IF(ISERROR(I28/D28*100),"0.00",I28/D28*100) -> 0.00 | H28: =IF(ISERROR(K28/D28*1000),"0",K28/D28*1000) -> 0 | I28: =I27+I38 -> 0 | K28: =K27+K38 -> 0
D29: 质检负责人： | K29: 制表人：
C34: 昨日月累：
B35: 原矿月累
B36: 铅精月累
B37: 锌精月累
B38: 尾矿月累
C44: 今日月累：
B45: 原矿月累 | D45: =D11 -> 0.00 | E45: =E11 -> 0 | F45: =F11 -> 0 | H45: =H11 -> 0 | L45: =L11 -> 0 | M45: =M11 -> 0 | N45: =N11 -> 0 | O45: =O11 -> 0
B46: 铅精月累 | D46: =D18 -> 0 | I46: =I18 -> 0 | J46: =J18 -> 0 | K46: =K18 -> 0
B47: 锌精月累 | D47: =D23 -> 0 | I47: =I23 -> 0 | J47: =J23 -> 0 | K47: =K23 -> 0
B48: 尾矿月累 | D48: =D28 -> 0 | I48: =I28 -> 0 | J48: =J28 -> 0 | K48: =K28 -> 0

Sheet 2车间表2
B2: 荣达选矿厂生产隆腾矿月累统计表 | O2: =(J13+K17)/(J7+K7)*100 -> #DIV/0!
O3: =(J14+K18)/(J8+K8)*100 -> #DIV/0!
J4: =基础数据!A2 -> 45836 | O4: =(J15+K19)/(J9+K9)*100 -> #DIV/0!
B5: 种类 | C5: 班别 | D5: 细度％ | E5: 磨矿时间（h） | F5: 干量（T） | G5: 原矿品位 | J5: 原矿金属量 | O5: =(J16+K20)/(J10+K10)*100 -> #DIV/0!
G6: 铅（%） | H6: 锌（%） | I6: 银（g/t） | J6: 铅（T） | K6: 锌（T） | L6: 银（Kg）
B7: 原矿 | C7: A月累 | D7: =IF(ISERROR((D32*F32+'2车间表1'!D7*'2车间表1'!H7)/'2车间表2'!F7),"0.00",(D32*F32+'2车间表1'!D7*'2车间表1'!H7)/'2车间表2'!F7) -> 0.00 | E7: =E32+'2车间表1'!E7 -> 0 | F7: =F32+'2车间表1'!H7 -> 0 | G7: =IF(ISERROR(J7/F7*100),"0.00",J7/F7*100) -> 0.00 | I7: =IF(ISERROR(L7/F7*1000),"0",L7/F7*1000) -> 0 | J7: =J32+'2车间表1'!M7 -> 0 | L7: =L32+'2车间表1'!O7 -> 0 | N7: =D7 -> 0.00 | O7: =F7/E7 -> #DIV/0! | P7: =#REF! -> #REF! | Q7: =G7 -> 0.00 | R7: =H7 -> 0 | S7: =I7 -> 0 | T7: =#REF! -> #REF! | U7: =#REF! -> #REF! | V7: =#REF! -> #REF! | W7: =#REF! -> #REF! | X7: =#REF! -> #REF! | Y7: =G13 -> 0.00 | Z7: =H13 -> 0 | AA7: =I13 -> 0 | AB7: =#REF! -> #REF! | AC7: =G17 -> 0 | AD7: =H17 -> 0 | AE7: =I17 -> 0 | AF7: =#REF! -> #REF! | AG7: =G21 -> 0.00 | AH7: =H21 -> 0 | AI7: =I21 -> 0 | AJ7: =#REF! -> #REF! | AK7: =D13 -> 0.00 | AL7: =D17 -> 0 | AM7: =E21 -> 0
C8: B月累 | D8: =IF(ISERROR((D33*F33+'2车间表1'!D8*'2车间表1'!H8)/'2车间表2'!F8),"0.00",(D33*F33+'2车间表1'!D8*'2车间表1'!H8)/'2车间表2'!F8) -> 0.00 | E8: =E33+'2车间表1'!E8 -> 0 | F8: =F33+'2车间表1'!H8 -> 0 | G8: =IF(ISERROR(J8/F8*100),"0.00",J8/F8*100) -> 0.00 | I8: =IF(ISERROR(L8/F8*1000),"0",L8/F8*1000) -> 0 | J8: =J33+'2车间表1'!M8 -> 0 | L8: =L33+'2车间表1'!O8 -> 0 | N8: =D8 -> 0.00 | O8: =F8/E8 -> #DIV/0! | P8: =#REF! -> #REF! | Q8: =G8 -> 0.00 | R8: =H8 -> 0 | S8: =I8 -> 0 | T8: =#REF! -> #REF! | U8: =#REF! -> #REF! | V8: =#REF! -> #REF! | W8: =#REF! -> #REF! | X8: =#REF! -> #REF! | Y8: =G14 -> 0.00 | Z8: =H14 -> 0 | AA8: =I14 -> 0 | AB8: =#REF! -> #REF! | AC8: =G18 -> 0 | AD8: =H18 -> 0 | AE8: =I18 -> 0 | AF8: =#REF! -> #REF! | AG8: =G22 -> 0.00 | AH8: =H22 -> 0 | AI8: =I22 -> 0 | AJ8: =#REF! -> #REF! | AK8: =D14 -> 0.00 | AL8: =D18 -> 0 | AM8: =E22 -> 0
C9: C月累 | D9: =IF(ISERROR((D34*F34+'2车间表1'!D9*'2车间表1'!H9)/'2车间表2'!F9),"0.00",(D34*F34+'2车间表1'!D9*'2车间表1'!H9)/'2车间表2'!F9) -> 0.00 | E9: =E34+'2车间表1'!E9 -> 0 | F9: =F34+'2车间表1'!H9 -> 0 | G9: =IF(ISERROR(J9/F9*100),"0.00",J9/F9*100) -> 0.00 | I9: =IF(ISERROR(L9/F9*1000),"0",L9/F9*1000) -> 0 | J9: =J34+'2车间表1'!M9 -> 0 | L9: =L34+'2车间表1'!O9 -> 0 | N9: =D9 -> 0.00 | O9: =F9/E9 -> #DIV/0! | P9: =#REF! -> #REF! | Q9: =G9 -> 0.00 | R9: =H9 -> 0 | S9: =I9 -> 0 | T9: =#REF! -> #REF! | U9: =#REF! -> #REF! | V9: =#REF! -> #REF! | W9: =#REF! -> #REF! | X9: =#REF! -> #REF! | Y9: =G15 -> 0.00 | Z9: =H15 -> 0 | AA9: =I15 -> 0 | AB9: =#REF! -> #REF! | AC9: =G19 -> 0 | AD9: =H19 -> 0 | AE9: =I19 -> 0 | AF9: =#REF! -> #REF! | AG9: =G23 -> 0.00 | AH9: =H23 -> 0 | AI9: =I23 -> 0 | AJ9: =#REF! -> #REF! | AK9: =D15 -> 0.00 | AL9: =D19 -> 0 | AM9: =E23 -> 0
C10: 月累 | D10: =IF(ISERROR((D7*F7+D8*F8+D9*F9)/F10),"0.00",(D7*F7+D8*F8+D9*F9)/F10) -> 0.00 | E10: =E7+E8+E9 -> 0 | F10: =F7+F8+F9 -> 0 | G10: =IF(ISERROR(J10/F10*100),"0.00",J10/F10*100) -> 0.00 | I10: =IF(ISERROR(L10/F10*1000),"0",L10/F10*1000) -> 0 | J10: =J7+J8+J9 -> 0 | L10: =L7+L8+L9 -> 0 | N10: =D10 -> 0.00 | O10: =F10/E10 -> #DIV/0! | P10: =#REF! -> #REF! | Q10: =G10 -> 0.00 | R10: =H10 -> 0 | S10: =I10 -> 0 | T10: =#REF! -> #REF! | U10: =#REF! -> #REF! | V10: =#REF! -> #REF! | W10: =#REF! -> #REF! | X10: =#REF! -> #REF! | Y10: =G16 -> 0.00 | Z10: =H16 -> 0 | AA10: =I16 -> 0 | AB10: =#REF! -> #REF! | AC10: =G20 -> 0 | AD10: =H20 -> 0 | AE10: =I20 -> 0 | AF10: =#REF! -> #REF! | AG10: =G24 -> 0.00 | AH10: =H24 -> 0 | AI10: =I24 -> 0 | AJ10: =#REF! -> #REF! | AK10: =D16 -> 0.00 | AL10: =D20 -> 0 | AM10: =E24 -> 0
B11: 种类 | C11: 班别 | D11: 回收率（%） | F11: 干量（T） | G11: 分 布 率 | J11: 金 属 量
D12: 铜铅锌 | E12: 银 | G12: 铅（%） | H12: 锌（%） | I12: 银（g/t） | J12: 铅（T） | L12: 银（Kg）
B13: 铅精 | C13: A月累 | D13: =IF(ISERROR(J13/J7*100),"0.00",J13/J7*100) -> 0.00 | E13: =IF(ISERROR(L13/L7*100),"0.00",L13/L7*100) -> 0.00 | F13: =F35+'2车间表1'!D14 -> 0 | G13: =IF(ISERROR(J13/F13*100),"0.00",J13/F13*100) -> 0.00 | I13: =IF(ISERROR(L13/F13*1000),"0",L13/F13*1000) -> 0 | J13: =J35+'2车间表1'!I14 -> 0 | L13: =L35+'2车间表1'!K14 -> 0 | N13: =#REF!/#REF!*100 -> #REF! | O13: =J13/J7*100 -> #DIV/0! | P13: =K13/K7*100 -> #DIV/0! | Q13: =L13/L7*100 -> #DIV/0! | S13: =P13 -> #DIV/0! | T13: =P17 -> #DIV/0! | U13: =#REF! -> #REF! | V13: =P21 -> #DIV/0! | W13: =S13+T13+U13+V13 -> #DIV/0!
C14: B月累 | D14: =IF(ISERROR(J14/J8*100),"0.00",J14/J8*100) -> 0.00 | E14: =IF(ISERROR(L14/L8*100),"0.00",L14/L8*100) -> 0.00 | F14: =F36+'2车间表1'!D15 -> 0 | G14: =IF(ISERROR(J14/F14*100),"0.00",J14/F14*100) -> 0.00 | I14: =IF(ISERROR(L14/F14*1000),"0",L14/F14*1000) -> 0 | J14: =J36+'2车间表1'!I15 -> 0 | L14: =L36+'2车间表1'!K15 -> 0 | N14: =#REF!/#REF!*100 -> #REF! | O14: =J14/J8*100 -> #DIV/0! | P14: =K14/K8*100 -> #DIV/0! | Q14: =L14/L8*100 -> #DIV/0! | S14: =P14 -> #DIV/0! | T14: =P18 -> #DIV/0! | U14: =#REF! -> #REF! | V14: =P22 -> #DIV/0! | W14: =S14+T14+U14+V14 -> #DIV/0!
C15: C月累 | D15: =IF(ISERROR(J15/J9*100),"0.00",J15/J9*100) -> 0.00 | E15: =IF(ISERROR(L15/L9*100),"0.00",L15/L9*100) -> 0.00 | F15: =F37+'2车间表1'!D16 -> 0 | G15: =IF(ISERROR(J15/F15*100),"0.00",J15/F15*100) -> 0.00 | I15: =IF(ISERROR(L15/F15*1000),"0",L15/F15*1000) -> 0 | J15: =J37+'2车间表1'!I16 -> 0 | L15: =L37+'2车间表1'!K16 -> 0 | N15: =#REF!/#REF!*100 -> #REF! | O15: =J15/J9*100 -> #DIV/0! | P15: =K15/K9*100 -> #DIV/0! | Q15: =L15/L9*100 -> #DIV/0! | S15: =P15 -> #DIV/0! | T15: =P19 -> #DIV/0! | U15: =#REF! -> #REF! | V15: =P23 -> #DIV/0! | W15: =S15+T15+U15+V15 -> #DIV/0!
C16: 月累 | D16: =IF(ISERROR(J16/J10*100),"0.00",J16/J10*100) -> 0.00 | E16: =IF(ISERROR(L16/L10*100),"0.00",L16/L10*100) -> 0.00 | F16: =F13+F14+F15 -> 0 | G16: =IF(ISERROR(J16/F16*100),"0.00",J16/F16*100) -> 0.00 | I16: =IF(ISERROR(L16/F16*1000),"0",L16/F16*1000) -> 0 | J16: =J13+J14+J15 -> 0 | L16: =L13+L14+L15 -> 0 | N16: =#REF!/#REF!*100 -> #REF! | O16: =J16/J10*100 -> #DIV/0! | P16: =K16/K10*100 -> #DIV/0! | Q16: =L16/L10*100 -> #DIV/0! | S16: =P16 -> #DIV/0! | T16: =P20 -> #DIV/0! | U16: =#REF! -> #REF! | V16: =P24 -> #DIV/0! | W16: =S16+T16+U16+V16 -> #DIV/0!
B17: 锌精 | C17: A月累 | N17: =#REF!/#REF!*100 -> #REF! | O17: =J17/J7*100 -> #DIV/0! | P17: =K17/K7*100 -> #DIV/0! | Q17: =L17/L7*100 -> #DIV/0! | S17: =N13 -> #REF! | T17: =N17 -> #REF! | U17: =#REF! -> #REF! | V17: =N21 -> #REF! | W17: =S17+T17+U17+V17 -> #REF!
C18: B月累 | N18: =#REF!/#REF!*100 -> #REF! | O18: =J18/J8*100 -> #DIV/0! | P18: =K18/K8*100 -> #DIV/0! | Q18: =L18/L8*100 -> #DIV/0! | S18: =N14 -> #REF! | T18: =N18 -> #REF! | U18: =#REF! -> #REF! | V18: =N22 -> #REF! | W18: =S18+T18+U18+V18 -> #REF!
C19: C月累 | N19: =#REF!/#REF!*100 -> #REF! | O19: =J19/J9*100 -> #DIV/0! | P19: =K19/K9*100 -> #DIV/0! | Q19: =L19/L9*100 -> #DIV/0! | S19: =N15 -> #REF! | T19: =N19 -> #REF! | U19: =#REF! -> #REF! | V19: =N23 -> #REF! | W19: =S19+T19+U19+V19 -> #REF!
C20: 月累 | N20: =#REF!/#REF!*100 -> #REF! | O20: =J20/J10*100 -> #DIV/0! | P20: =K20/K10*100 -> #DIV/0! | Q20: =L20/L10*100 -> #DIV/0! | S20: =N16 -> #REF! | T20: =N20 -> #REF! | U20: =#REF! -> #REF! | V20: =N24 -> #REF! | W20: =S20+T20+U20+V20 -> #REF!
B21: 尾矿 | C21: A月累 | F21: =F41+'2车间表1'!D24 -> 0 | G21: =IF(ISERROR(J21/F21*100),"0.00",J21/F21*100) -> 0.00 | I21: =IF(ISERROR(L21/F21*1000),"0",L21/F21*1000) -> 0 | J21: =J41+'2车间表1'!I24 -> 0 | L21: =L41+'2车间表1'!K24 -> 0 | N21: =#REF!/#REF!*100 -> #REF! | O21: =J21/J7*100 -> #DIV/0! | P21: =K21/K7*100 -> #DIV/0! | Q21: =L21/L7*100 -> #DIV/0! | S21: =Q13 -> #DIV/0! | T21: =Q17 -> #DIV/0! | U21: =#REF! -> #REF! | V21: =Q21 -> #DIV/0! | W21: =S21+T21+U21+V21 -> #DIV/0!
C22: B月累 | F22: =F42+'2车间表1'!D25 -> 0 | G22: =IF(ISERROR(J22/F22*100),"0.00",J22/F22*100) -> 0.00 | I22: =IF(ISERROR(L22/F22*1000),"0",L22/F22*1000) -> 0 | J22: =J42+'2车间表1'!I25 -> 0 | L22: =L42+'2车间表1'!K25 -> 0 | N22: =#REF!/#REF!*100 -> #REF! | O22: =J22/J8*100 -> #DIV/0! | P22: =K22/K8*100 -> #DIV/0! | Q22: =L22/L8*100 -> #DIV/0! | S22: =Q14 -> #DIV/0! | T22: =Q18 -> #DIV/0! | U22: =#REF! -> #REF! | V22: =Q22 -> #DIV/0! | W22: =S22+T22+U22+V22 -> #DIV/0!
C23: C月累 | F23: =F43+'2车间表1'!D26 -> 0 | G23: =IF(ISERROR(J23/F23*100),"0.00",J23/F23*100) -> 0.00 | I23: =IF(ISERROR(L23/F23*1000),"0",L23/F23*1000) -> 0 | J23: =J43+'2车间表1'!I26 -> 0 | L23: =L43+'2车间表1'!K26 -> 0 | N23: =#REF!/#REF!*100 -> #REF! | O23: =J23/J9*100 -> #DIV/0! | P23: =K23/K9*100 -> #DIV/0! | Q23: =L23/L9*100 -> #DIV/0! | S23: =Q15 -> #DIV/0! | T23: =Q19 -> #DIV/0! | U23: =#REF! -> #REF! | V23: =Q23 -> #DIV/0! | W23: =S23+T23+U23+V23 -> #DIV/0!
C24: 月累 | F24: =F21+F22+F23 -> 0 | G24: =IF(ISERROR(J24/F24*100),"0.00",J24/F24*100) -> 0.00 | I24: =IF(ISERROR(L24/F24*1000),"0",L24/F24*1000) -> 0 | J24: =J21+J22+J23 -> 0 | L24: =L21+L22+L23 -> 0 | N24: =#REF!/#REF!*100 -> #REF! | O24: =J24/J10*100 -> #DIV/0! | P24: =K24/K10*100 -> #DIV/0! | Q24: =L24/L10*100 -> #DIV/0! | S24: =Q16 -> #DIV/0! | T24: =Q20 -> #DIV/0! | U24: =#REF! -> #REF! | V24: =Q24 -> #DIV/0! | W24: =S24+T24+U24+V24 -> #DIV/0!
C25: 质检负责人：
D29: 昨日月累：
B30: 种类 | C30: 班别 | D30: 细度％ | E30: 磨矿时间（h） | F30: 干量（T） | G30: 金属量 | J30: 金属量
G31: 铅（%） | H31: 锌（%） | I31: 银（g/t） | J31: 铅（T） | K31: 锌（T） | L31: 银（Kg）
B32: 原矿 | C32: 一月累
C33: 二月累
C34: 三月累
B35: 铅精 | C35: 一月累
C36: 二月累
C37: 三月累
B38: 锌精 | C38: 一月累
C39: 二月累
C40: 三月累
B41: 尾矿 | C41: 一月累
C42: 二月累
C43: 三月累
D46: 今日月累：
...

Sheet 2车间表3
B2: 荣达选矿厂生产隆腾矿年累统计表 | O2: =(J13+K17)/(J7+K7)*100 -> #DIV/0!
O3: =(J14+K18)/(J8+K8)*100 -> #DIV/0!
J4: =基础数据!A2 -> 45836 | O4: =(J15+K19)/(J9+K9)*100 -> #DIV/0!
B5: 种类 | C5: 班别 | D5: 细度％ | E5: 磨矿时间（h） | F5: 干量（T） | G5: 原矿品位 | J5: 原矿金属量 | O5: =(J16+K20)/(J10+K10)*100 -> #DIV/0!
G6: 铅（%） | H6: 锌（%） | I6: 银（g/t） | J6: 铅（T） | K6: 锌（T） | L6: 银（Kg）
B7: 原矿 | C7: A年累 | D7: =IF(ISERROR((D32*F32+'2车间表1'!D7*'2车间表1'!H7)/'2车间表3'!F7),"0.00",(D32*F32+'2车间表1'!D7*'2车间表1'!H7)/'2车间表3'!F7) -> 0.00 | E7: =E32+'2车间表1'!E7 -> 0 | F7: =F32+'2车间表1'!H7 -> 0 | G7: =IF(ISERROR(J7/F7*100),"0.00",J7/F7*100) -> 0.00 | I7: =IF(ISERROR(L7/F7*1000),"0.00",L7/F7*1000) -> 0.00 | J7: =J32+'2车间表1'!M7 -> 0 | L7: =L32+'2车间表1'!O7 -> 0 | N7: =D7 -> 0.00 | O7: =F7/E7 -> #DIV/0! | P7: =#REF! -> #REF! | Q7: =G7 -> 0.00 | R7: =H7 -> 0 | S7: =I7 -> 0.00 | T7: =#REF! -> #REF! | U7: =#REF! -> #REF! | V7: =#REF! -> #REF! | W7: =#REF! -> #REF! | X7: =#REF! -> #REF! | Y7: =G13 -> 0.00 | Z7: =H13 -> 0 | AA7: =I13 -> 0.00 | AB7: =#REF! -> #REF! | AC7: =G17 -> 0 | AD7: =H17 -> 0 | AE7: =I17 -> 0 | AF7: =#REF! -> #REF! | AG7: =G21 -> 0.00 | AH7: =H21 -> 0 | AI7: =I21 -> 0.00 | AJ7: =#REF! -> #REF! | AK7: =D13 -> 0.00 | AL7: =D17 -> 0 | AM7: =E21 -> 0
C8: B年累 | D8: =IF(ISERROR((D33*F33+'2车间表1'!D8*'2车间表1'!H8)/'2车间表3'!F8),"0.00",(D33*F33+'2车间表1'!D8*'2车间表1'!H8)/'2车间表3'!F8) -> 0.00 | E8: =E33+'2车间表1'!E8 -> 0 | F8: =F33+'2车间表1'!H8 -> 0 | G8: =IF(ISERROR(J8/F8*100),"0.00",J8/F8*100) -> 0.00 | I8: =IF(ISERROR(L8/F8*1000),"0.00",L8/F8*1000) -> 0.00 | J8: =J33+'2车间表1'!M8 -> 0 | L8: =L33+'2车间表1'!O8 -> 0 | N8: =D8 -> 0.00 | O8: =F8/E8 -> #DIV/0! | P8: =#REF! -> #REF! | Q8: =G8 -> 0.00 | R8: =H8 -> 0 | S8: =I8 -> 0.00 | T8: =#REF! -> #REF! | U8: =#REF! -> #REF! | V8: =#REF! -> #REF! | W8: =#REF! -> #REF! | X8: =#REF! -> #REF! | Y8: =G14 -> 0.00 | Z8: =H14 -> 0 | AA8: =I14 -> 0.00 | AB8: =#REF! -> #REF! | AC8: =G18 -> 0 | AD8: =H18 -> 0 | AE8: =I18 -> 0 | AF8: =#REF! -> #REF! | AG8: =G22 -> 0.00 | AH8: =H22 -> 0 | AI8: =I22 -> 0.00 | AJ8: =#REF! -> #REF! | AK8: =D14 -> 0.00 | AL8: =D18 -> 0 | AM8: =E22 -> 0
C9: C年累 | D9: =IF(ISERROR((D34*F34+'2车间表1'!D9*'2车间表1'!H9)/'2车间表3'!F9),"0.00",(D34*F34+'2车间表1'!D9*'2车间表1'!H9)/'2车间表3'!F9) -> 0.00 | E9: =E34+'2车间表1'!E9 -> 0 | F9: =F34+'2车间表1'!H9 -> 0 | G9: =IF(ISERROR(J9/F9*100),"0.00",J9/F9*100) -> 0.00 | I9: =IF(ISERROR(L9/F9*1000),"0.00",L9/F9*1000) -> 0.00 | J9: =J34+'2车间表1'!M9 -> 0 | L9: =L34+'2车间表1'!O9 -> 0 | N9: =D9 -> 0.00 | O9: =F9/E9 -> #DIV/0! | P9: =#REF! -> #REF! | Q9: =G9 -> 0.00 | R9: =H9 -> 0 | S9: =I9 -> 0.00 | T9: =#REF! -> #REF! | U9: =#REF! -> #REF! | V9: =#REF! -> #REF! | W9: =#REF! -> #REF! | X9: =#REF! -> #REF! | Y9: =G15 -> 0.00 | Z9: =H15 -> 0 | AA9: =I15 -> 0.00 | AB9: =#REF! -> #REF! | AC9: =G19 -> 0 | AD9: =H19 -> 0 | AE9: =I19 -> 0 | AF9: =#REF! -> #REF! | AG9: =G23 -> 0.00 | AH9: =H23 -> 0 | AI9: =I23 -> 0.00 | AJ9: =#REF! -> #REF! | AK9: =D15 -> 0.00 | AL9: =D19 -> 0 | AM9: =E23 -> 0
C10: 年累 | D10: =IF(ISERROR((D7*F7+D8*F8+D9*F9)/F10),"0.00",(D7*F7+D8*F8+D9*F9)/F10) -> 0.00 | E10: =E7+E8+E9 -> 0 | F10: =F7+F8+F9 -> 0 | G10: =IF(ISERROR(J10/F10*100),"0.00",J10/F10*100) -> 0.00 | I10: =IF(ISERROR(L10/F10*1000),"0.00",L10/F10*1000) -> 0.00 | J10: =J7+J8+J9 -> 0 | L10: =L7+L8+L9 -> 0 | N10: =D10 -> 0.00 | O10: =F10/E10 -> #DIV/0! | P10: =#REF! -> #REF! | Q10: =G10 -> 0.00 | R10: =H10 -> 0 | S10: =I10 -> 0.00 | T10: =#REF! -> #REF! | U10: =#REF! -> #REF! | V10: =#REF! -> #REF! | W10: =#REF! -> #REF! | X10: =#REF! -> #REF! | Y10: =G16 -> 0.00 | Z10: =H16 -> 0 | AA10: =I16 -> 0.00 | AB10: =#REF! -> #REF! | AC10: =G20 -> 0 | AD10: =H20 -> 0 | AE10: =I20 -> 0 | AF10: =#REF! -> #REF! | AG10: =G24 -> 0.00 | AH10: =H24 -> 0 | AI10: =I24 -> 0.00 | AJ10: =#REF! -> #REF! | AK10: =D16 -> 0.00 | AL10: =D20 -> 0 | AM10: =E24 -> 0
B11: 种类 | C11: 班别 | D11: 回收率（%） | F11: 干量（T） | G11: 分 布 率 | J11: 金 属 量
D12: 铜铅锌 | E12: 银 | G12: 铅（%） | H12: 锌（%） | I12: 银（g/t） | J12: 铅（T） | K12: 锌（T） | L12: 银（Kg）
B13: 铅精 | C13: A年累 | D13: =IF(ISERROR(J13/J7*100),"0.00",J13/J7*100) -> 0.00 | E13: =IF(ISERROR(L13/L7*100),"0.00",L13/L7*100) -> 0.00 | F13: =F35+'2车间表1'!D14 -> 0 | G13: =IF(ISERROR(J13/F13*100),"0.00",J13/F13*100) -> 0.00 | I13: =IF(ISERROR(L13/F13*1000),"0.00",L13/F13*1000) -> 0.00 | J13: =J35+'2车间表1'!I14 -> 0 | L13: =L35+'2车间表1'!K14 -> 0 | N13: =#REF!/#REF!*100 -> #REF! | O13: =J13/J7*100 -> #DIV/0! | P13: =K13/K7*100 -> #DIV/0! | Q13: =L13/L7*100 -> #DIV/0! | S13: =P13 -> #DIV/0! | T13: =P17 -> #DIV/0! | U13: =#REF! -> #REF! | V13: =P21 -> #DIV/0! | W13: =S13+T13+U13+V13 -> #DIV/0!
C14: B年累 | D14: =IF(ISERROR(J14/J8*100),"0.00",J14/J8*100) -> 0.00 | E14: =IF(ISERROR(L14/L8*100),"0.00",L14/L8*100) -> 0.00 | F14: =F36+'2车间表1'!D15 -> 0 | G14: =IF(ISERROR(J14/F14*100),"0.00",J14/F14*100) -> 0.00 | I14: =IF(ISERROR(L14/F14*1000),"0.00",L14/F14*1000) -> 0.00 | J14: =J36+'2车间表1'!I15 -> 0 | L14: =L36+'2车间表1'!K15 -> 0 | N14: =#REF!/#REF!*100 -> #REF! | O14: =J14/J8*100 -> #DIV/0! | P14: =K14/K8*100 -> #DIV/0! | Q14: =L14/L8*100 -> #DIV/0! | S14: =P14 -> #DIV/0! | T14: =P18 -> #DIV/0! | U14: =#REF! -> #REF! | V14: =P22 -> #DIV/0! | W14: =S14+T14+U14+V14 -> #DIV/0!
C15: C年累 | D15: =IF(ISERROR(J15/J9*100),"0.00",J15/J9*100) -> 0.00 | E15: =IF(ISERROR(L15/L9*100),"0.00",L15/L9*100) -> 0.00 | F15: =F37+'2车间表1'!D16 -> 0 | G15: =IF(ISERROR(J15/F15*100),"0.00",J15/F15*100) -> 0.00 | I15: =IF(ISERROR(L15/F15*1000),"0.00",L15/F15*1000) -> 0.00 | J15: =J37+'2车间表1'!I16 -> 0 | L15: =L37+'2车间表1'!K16 -> 0 | N15: =#REF!/#REF!*100 -> #REF! | O15: =J15/J9*100 -> #DIV/0! | P15: =K15/K9*100 -> #DIV/0! | Q15: =L15/L9*100 -> #DIV/0! | S15: =P15 -> #DIV/0! | T15: =P19 -> #DIV/0! | U15: =#REF! -> #REF! | V15: =P23 -> #DIV/0! | W15: =S15+T15+U15+V15 -> #DIV/0!
C16: 年累 | D16: =IF(ISERROR(J16/J10*100),"0.00",J16/J10*100) -> 0.00 | E16: =IF(ISERROR(L16/L10*100),"0.00",L16/L10*100) -> 0.00 | F16: =F13+F14+F15 -> 0 | G16: =IF(ISERROR(J16/F16*100),"0.00",J16/F16*100) -> 0.00 | I16: =IF(ISERROR(L16/F16*1000),"0.00",L16/F16*1000) -> 0.00 | J16: =J13+J14+J15 -> 0 | L16: =L13+L14+L15 -> 0 | N16: =#REF!/#REF!*100 -> #REF! | O16: =J16/J10*100 -> #DIV/0! | P16: =K16/K10*100 -> #DIV/0! | Q16: =L16/L10*100 -> #DIV/0! | S16: =P16 -> #DIV/0! | T16: =P20 -> #DIV/0! | U16: =#REF! -> #REF! | V16: =P24 -> #DIV/0! | W16: =S16+T16+U16+V16 -> #DIV/0!
B17: 锌精 | C17: A年累 | N17: =#REF!/#REF!*100 -> #REF! | O17: =J17/J7*100 -> #DIV/0! | P17: =K17/K7*100 -> #DIV/0! | Q17: =L17/L7*100 -> #DIV/0! | S17: =N13 -> #REF! | T17: =N17 -> #REF! | U17: =#REF! -> #REF! | V17: =N21 -> #REF! | W17: =S17+T17+U17+V17 -> #REF!
C18: B年累 | N18: =#REF!/#REF!*100 -> #REF! | O18: =J18/J8*100 -> #DIV/0! | P18: =K18/K8*100 -> #DIV/0! | Q18: =L18/L8*100 -> #DIV/0! | S18: =N14 -> #REF! | T18: =N18 -> #REF! | U18: =#REF! -> #REF! | V18: =N22 -> #REF! | W18: =S18+T18+U18+V18 -> #REF!
